Workbook

Sheet Інструкція
B2: BEEF — графік роботи персоналу, жовтень 2026
B3: Робочий документ для менеджменту. Версія 1.0. Чисельність і норми — проєктні, підлягають калібруванню за фактичними даними.
B6: Режим роботи ресторану
B7: Неділя, понеділок, вівторок — 10:00–22:00. Середа, четвер, п'ятниця, субота — 10:00–23:00.
B9: Як побудовано графік
B10: 1. Завантаження оцінено за днями тижня (аркуш «Норми»): Пн–Вт низьке, Ср середнє, Чт і Нд високе, Пт–Сб пікове.
B11: 2. Для кожної посади задано норму: скільки людей потрібно на кожну зміну в кожен день тижня.
B12: 3. Замість двох довгих змін використано чотири типи змін (аркуш «Зміни»): ранкова, середня, вечірня та пікова. Це дає змогу додавати людей лише в години піку, а не на весь день — фонд годин витрачається там, де є гості.
B13: 4. Розподіл змін між співробітниками виконано алгоритмом оптимізації з жорсткими правилами (нижче). Години в межах посади вирівняні, п'ятниці та суботи розподілені рівномірно.
B15: Обов'язкові правила графіка
B16: • Після вечірньої (В), середньої (С) або пікової (П) зміни наступного дня ранкова (Р) зміна заборонена. Причина: ст. 59 КЗпП — перерва між змінами не менше подвійної тривалості попередньої зміни; крім того, працівник після закриття о 23:30 не може якісно відкрити зал о 09:30.
B17: • Не більше 5 робочих днів поспіль (щотижневий безперервний відпочинок, ст. 70 КЗпП).
... B37: • Офіціанти, сомельє та бармени отримують на щоденному брифінгу (09:40 і 16:10) розподіл зон і стоп-лист; час брифінгу вже входить у зміну.

Sheet Зміни
A1: Типи змін, час і години
A2: Час роботи ресторану: Нд–Вт 10:00–22:00; Ср–Сб 10:00–23:00. Персонал приходить за 30 хв до відкриття і залишається 30 хв після закриття.
A4: Код | B4: Зміна | C4: Пн | D4: Вт | E4: Ср | F4: Чт | G4: Пт | H4: Сб | I4: Нд | J4: Призначення
A5: Р | B5: Ранкова | C5: 09:30–17:00 | D5: 09:30–17:00 | E5: 09:30–17:00 | F5: 09:30–17:00 | G5: 09:30–17:00 | H5: 09:30–17:00 | I5: 09:30–17:00 | J5: Відкриття, підготовка залу/цехів, ланч, бізнес-ланч
A6: С | B6: Середня (денний пік) | C6: 12:00–20:00 | D6: 12:00–20:00 | E6: 12:00–20:00 | F6: 12:00–20:00 | G6: 12:00–20:00 | H6: 12:00–20:00 | I6: 12:00–20:00 | J6: Підсилення денного піку та раннього вечора (Чт–Нд)
A7: В | B7: Вечірня | C7: 15:00–22:30 | D7: 15:00–22:30 | E7: 16:00–23:30 | F7: 16:00–23:30 | G7: 16:00–23:30 | H7: 16:00–23:30 | I7: 15:30–22:30 | J7: Вечірній сервіс, закриття зміни, прибирання, касові звіти
A8: П | B8: Пікова вечірня | C8: — | D8: — | E8: — | F8: 17:30–23:30 | G8: 17:30–23:30 | H8: 17:30–23:30 | I8: — | J8: Підсилення вечірнього піку 19:00–22:00 і закриття (Чт–Сб)
A11: Оплачувані години зміни (вхідні дані)
A12: Код | B12: Зміна | C12: Пн | D12: Вт | E12: Ср | F12: Чт | G12: Пт | H12: Сб | I12: Нд
A13: Р | B13: Ранкова | C13: 7.5 | D13: 7.5 | E13: 7.5 | F13: 7.5 | G13: 7.5 | H13: 7.5 | I13: 7.5
A14: С | B14: Середня (денний пік) | C14: 8 | D14: 8 | E14: 8 | F14: 8 | G14: 8 | H14: 8 | I14: 8
A15: В | B15: Вечірня | C15: 7.5 | D15: 7.5 | E15: 7.5 | F15: 7.5 | G15: 7.5 | H15: 7.5 | I15: 7
A16: П | B16: Пікова вечірня | C16: 6 | D16: 6 | E16: 6 | F16: 6 | G16: 6 | H16: 6 | I16: 6
A19: Норма робочого часу на місяць, год | C19: 176
A21: Правила поєднання змін
A22: • Р → будь-яка зміна наступного дня: дозволено.
A23: • С, В, П → Р наступного дня: заборонено (міжзмінний відпочинок, ст. 59 КЗпП). Після вечора — вечір, середня або вихідний.
A24: • Не більше 5 робочих днів поспіль.
A25: • Під час зміни мають бути 30 хв перекриття «ранок–вечір» для передачі зміни (16:00–17:00 / 15:00–17:00).

Sheet Норми
A1: Профіль завантаження та норми укомплектування
A2: Рівні завантаження — експертне припущення до отримання даних POS. Норми (сині) можна змінювати; контроль покриття в графіках перерахується автоматично.
A4: День тижня | C4: Пн | D4: Вт | E4: Ср | F4: Чт | G4: Пт | H4: Сб | I4: Нд
A5: Рівень завантаження | C5: Низький | D5: Низький | E5: Середній | F5: Високий | G5: Піковий | H5: Піковий | I5: Високий
A6: Режим роботи | C6: 10–22 | D6: 10–22 | E6: 10–23 | F6: 10–23 | G6: 10–23 | H6: 10–23 | I6: 10–22
A7: Днів у жовтні | C7: 4 | D7: 4 | E7: 4 | F7: 5 | G7: 5 | H7: 5 | I7: 4
A8: Обґрунтування рівня | C8: Повільний старт тижня; основний потік — ділові ланчі | D8: Аналогічно понеділку | E8: Перший день подовженого режиму до 23:00; вечір помірний | F8: Ділові вечері, початок «вечорів вихідних» | G8: Максимальна вечірня посадка, банкети, винні замовлення | H8: Високий день і найвищий вечір тижня | I8: Сімейний ланч і ранній вечір; закриття о 22:00
A10: Норми: кількість людей на зміну
A11: Посада | B11: Зміна | C11: Пн | D11: Вт | E11: Ср | F11: Чт | G11: Пт | H11: Сб | I11: Нд | J11: Змін/міс. | L11: Ключ (службовий)
A12: ЗАЛ
A13: Менеджер зміни | B13: Р | C13: 1 | D13: 1 | E13: 1 | F13: 1 | G13: 1 | H13: 1 | I13: 1 | J13: =SUMPRODUCT(C13:I13,$C$7:$I$7) -> 31 | L13: =A13&"|"&B13 -> Менеджер зміни|Р
A14: Менеджер зміни | B14: В | C14: 1 | D14: 1 | E14: 1 | F14: 1 | G14: 1 | H14: 1 | I14: 1 | J14: =SUMPRODUCT(C14:I14,$C$7:$I$7) -> 31 | L14: =A14&"|"&B14 -> Менеджер зміни|В
A15: Хостес | B15: Р | C15: 1 | D15: 1 | E15: 1 | F15: 1 | G15: 1 | H15: 1 | I15: 1 | J15: =SUMPRODUCT(C15:I15,$C$7:$I$7) -> 31 | L15: =A15&"|"&B15 -> Хостес|Р
A16: Хостес | B16: С | C16: 0 | D16: 0 | E16: 0 | F16: 0 | G16: 0 | H16: 0 | I16: 1 | J16: =SUMPRODUCT(C16:I16,$C$7:$I$7) -> 4 | L16: =A16&"|"&B16 -> Хостес|С
A17: Хостес | B17: В | C17: 1 | D17: 1 | E17: 1 | F17: 1 | G17: 1 | H17: 1 | I17: 1 | J17: =SUMPRODUCT(C17:I17,$C$7:$I$7) -> 31 | L17: =A17&"|"&B17 -> Хостес|В
A18: Хостес | B18: П | C18: 0 | D18: 0 | E18: 0 | F18: 0 | G18: 1 | H18: 1 | I18: 0 | J18: =SUMPRODUCT(C18:I18,$C$7:$I$7) -> 10 | L18: =A18&"|"&B18 -> Хостес|П
A19: Офіціант | B19: Р | C19: 2 | D19: 2 | E19: 2 | F19: 2 | G19: 3 | H19: 3 | I19: 3 | J19: =SUMPRODUCT(C19:I19,$C$7:$I$7) -> 76 | L19: =A19&"|"&B19 -> Офіціант|Р
A20: Офіціант | B20: С | C20: 0 | D20: 0 | E20: 0 | F20: 1 | G20: 1 | H20: 2 | I20: 2 | J20: =SUMPRODUCT(C20:I20,$C$7:$I$7) -> 28 | L20: =A20&"|"&B20 -> Офіціант|С
A21: Офіціант | B21: В | C21: 2 | D21: 2 | E21: 3 | F21: 3 | G21: 4 | H21: 4 | I21: 3 | J21: =SUMPRODUCT(C21:I21,$C$7:$I$7) -> 95 | L21: =A21&"|"&B21 -> Офіціант|В
A22: Офіціант | B22: П | C22: 0 | D22: 0 | E22: 0 | F22: 1 | G22: 2 | H22: 2 | I22: 0 | J22: =SUMPRODUCT(C22:I22,$C$7:$I$7) -> 25 | L22: =A22&"|"&B22 -> Офіціант|П
A23: Ранер | B23: Р | C23: 1 | D23: 1 | E23: 1 | F23: 1 | G23: 1 | H23: 2 | I23: 2 | J23: =SUMPRODUCT(C23:I23,$C$7:$I$7) -> 40 | L23: =A23&"|"&B23 -> Ранер|Р
A24: Ранер | B24: С | C24: 0 | D24: 0 | E24: 0 | F24: 0 | G24: 1 | H24: 1 | I24: 1 | J24: =SUMPRODUCT(C24:I24,$C$7:$I$7) -> 14 | L24: =A24&"|"&B24 -> Ранер|С
... A31: Бармен | B31: П | C31: 0 | D31: 0 | E31: 0 | F31: 0 | G31: 1 | H31: 1 | I31: 0 | J31: =SUMPRODUCT(C31:I31,$C$7:$I$7) -> 10 | L31: =A31&"|"&B31 -> Бармен|П
A32: КУХНЯ
A33: Су-шеф | B33: Р | C33: 1 | D33: 1 | E33: 1 | F33: 1 | G33: 1 | H33: 1 | I33: 1 | J33: =SUMPRODUCT(C33:I33,$C$7:$I$7) -> 31 | L33: =A33&"|"&B33 -> Су-шеф|Р
A34: Су-шеф | B34: В | C34: 1 | D34: 1 | E34: 1 | F34: 1 | G34: 1 | H34: 1 | I34: 1 | J34: =SUMPRODUCT(C34:I34,$C$7:$I$7) -> 31 | L34: =A34&"|"&B34 -> Су-шеф|В
A35: Кухар гриль | B35: Р | C35: 1 | D35: 1 | E35: 1 | F35: 1 | G35: 1 | H35: 1 | I35: 1 | J35: =SUMPRODUCT(C35:I35,$C$7:$I$7) -> 31 | L35: =A35&"|"&B35 -> Кухар гриль|Р
A36: Кухар гриль | B36: С | C36: 0 | D36: 0 | E36: 0 | F36: 0 | G36: 1 | H36: 1 | I36: 1 | J36: =SUMPRODUCT(C36:I36,$C$7:$I$7) -> 14 | L36: =A36&"|"&B36 -> Кухар гриль|С
A37: Кухар гриль | B37: В | C37: 1 | D37: 1 | E37: 1 | F37: 2 | G37: 2 | H37: 2 | I37: 1 | J37: =SUMPRODUCT(C37:I37,$C$7:$I$7) -> 46 | L37: =A37&"|"&B37 -> Кухар гриль|В
A38: Кухар гарячого цеху | B38: Р | C38: 1 | D38: 1 | E38: 1 | F38: 1 | G38: 1 | H38: 1 | I38: 1 | J38: =SUMPRODUCT(C38:I38,$C$7:$I$7) -> 31 | L38: =A38&"|"&B38 -> Кухар гарячого цеху|Р
A39: Кухар гарячого цеху | B39: С | C39: 0 | D39: 0 | E39: 0 | F39: 0 | G39: 0 | H39: 1 | I39: 1 | J39: =SUMPRODUCT(C39:I39,$C$7:$I$7) -> 9 | L39: =A39&"|"&B39 -> Кухар гарячого цеху|С
A40: Кухар гарячого цеху | B40: В | C40: 1 | D40: 1 | E40: 1 | F40: 1 | G40: 2 | H40: 2 | I40: 1 | J40: =SUMPRODUCT(C40:I40,$C$7:$I$7) -> 41 | L40: =A40&"|"&B40 -> Кухар гарячого цеху|В
A41: Кухар холодного цеху | B41: Р | C41: 1 | D41: 1 | E41: 1 | F41: 1 | G41: 1 | H41: 1 | I41: 1 | J41: =SUMPRODUCT(C41:I41,$C$7:$I$7) -> 31 | L41: =A41&"|"&B41 -> Кухар холодного цеху|Р
A42: Кухар холодного цеху | B42: С | C42: 0 | D42: 0 | E42: 0 | F42: 0 | G42: 1 | H42: 1 | I42: 0 | J42: =SUMPRODUCT(C42:I42,$C$7:$I$7) -> 10 | L42: =A42&"|"&B42 -> Кухар холодного цеху|С
A43: Кухар холодного цеху | B43: В | C43: 1 | D43: 1 | E43: 1 | F43: 1 | G43: 1 | H43: 1 | I43: 1 | J43: =SUMPRODUCT(C43:I43,$C$7:$I$7) -> 31 | L43: =A43&"|"&B43 -> Кухар холодного цеху|В
A44: Кондитер | B44: Р | C44: 1 | D44: 1 | E44: 1 | F44: 1 | G44: 1 | H44: 1 | I44: 1 | J44: =SUMPRODUCT(C44:I44,$C$7:$I$7) -> 31 | L44: =A44&"|"&B44 -> Кондитер|Р
... A47: Мийник | B47: П | C47: 0 | D47: 0 | E47: 0 | F47: 0 | G47: 1 | H47: 1 | I47: 0 | J47: =SUMPRODUCT(C47:I47,$C$7:$I$7) -> 10 | L47: =A47&"|"&B47 -> Мийник|П

Sheet Зведення
A1: Зведення: чисельність і фонд робочого часу
A2: Усі показники розраховуються з аркушів графіка.
A4: Підрозділ | B4: Посада | C4: Людей | D4: Годин разом | E4: Середнє | F4: Мін. | G4: Макс. | H4: Сер. до норми
A5: ЗАЛ | B5: Менеджер зміни | C5: =COUNTA('Графік Зал'!C13:C15) -> 3 | D5: =SUM('Графік Зал'!AJ13:AJ15) -> 463 | E5: =IF(C5=0,0,D5/C5) -> 154.33333 | F5: =MIN('Графік Зал'!AJ13:AJ15) -> 149.5 | G5: =MAX('Графік Зал'!AJ13:AJ15) -> 157 | H5: =E5-Зміни!$C$19 -> -21.666667
A6: ЗАЛ | B6: Хостес | C6: =COUNTA('Графік Зал'!C20:C23) -> 4 | D6: =SUM('Графік Зал'!AJ20:AJ23) -> 555 | E6: =IF(C6=0,0,D6/C6) -> 138.75 | F6: =MIN('Графік Зал'!AJ20:AJ23) -> 138 | G6: =MAX('Графік Зал'!AJ20:AJ23) -> 139.5 | H6: =E6-Зміни!$C$19 -> -37.25
A7: ЗАЛ | B7: Офіціант | C7: =COUNTA('Графік Зал'!C30:C40) -> 11 | D7: =SUM('Графік Зал'!AJ30:AJ40) -> 1650.5 | E7: =IF(C7=0,0,D7/C7) -> 150.04545 | F7: =MIN('Графік Зал'!AJ30:AJ40) -> 149 | G7: =MAX('Графік Зал'!AJ30:AJ40) -> 151.5 | H7: =E7-Зміни!$C$19 -> -25.954545
A8: ЗАЛ | B8: Ранер | C8: =COUNTA('Графік Зал'!C47:C52) -> 6 | D8: =SUM('Графік Зал'!AJ47:AJ52) -> 815 | E8: =IF(C8=0,0,D8/C8) -> 135.83333 | F8: =MIN('Графік Зал'!AJ47:AJ52) -> 134.5 | G8: =MAX('Графік Зал'!AJ47:AJ52) -> 137 | H8: =E8-Зміни!$C$19 -> -40.166667
A9: ЗАЛ | B9: Сомельє | C9: =COUNTA('Графік Зал'!C59:C60) -> 2 | D9: =SUM('Графік Зал'!AJ59:AJ60) -> 350.5 | E9: =IF(C9=0,0,D9/C9) -> 175.25 | F9: =MIN('Графік Зал'!AJ59:AJ60) -> 174.5 | G9: =MAX('Графік Зал'!AJ59:AJ60) -> 176 | H9: =E9-Зміни!$C$19 -> -0.75
A10: ЗАЛ | B10: Бармен | C10: =COUNTA('Графік Зал'!C65:C68) -> 4 | D10: =SUM('Графік Зал'!AJ65:AJ68) -> 523 | E10: =IF(C10=0,0,D10/C10) -> 130.75 | F10: =MIN('Графік Зал'!AJ65:AJ68) -> 130 | G10: =MAX('Графік Зал'!AJ65:AJ68) -> 131.5 | H10: =E10-Зміни!$C$19 -> -45.25
A11: КУХНЯ | B11: Су-шеф | C11: =COUNTA('Графік Кухня'!C13:C15) -> 3 | D11: =SUM('Графік Кухня'!AJ13:AJ15) -> 463 | E11: =IF(C11=0,0,D11/C11) -> 154.33333 | F11: =MIN('Графік Кухня'!AJ13:AJ15) -> 149.5 | G11: =MAX('Графік Кухня'!AJ13:AJ15) -> 157 | H11: =E11-Зміни!$C$19 -> -21.666667
A12: КУХНЯ | B12: Кухар гриль | C12: =COUNTA('Графік Кухня'!C20:C23) -> 4 | D12: =SUM('Графік Кухня'!AJ20:AJ23) -> 687.5 | E12: =IF(C12=0,0,D12/C12) -> 171.875 | F12: =MIN('Графік Кухня'!AJ20:AJ23) -> 171 | G12: =MAX('Графік Кухня'!AJ20:AJ23) -> 172.5 | H12: =E12-Зміни!$C$19 -> -4.125
A13: КУХНЯ | B13: Кухар гарячого цеху | C13: =COUNTA('Графік Кухня'!C29:C32) -> 4 | D13: =SUM('Графік Кухня'!AJ29:AJ32) -> 610 | E13: =IF(C13=0,0,D13/C13) -> 152.5 | F13: =MIN('Графік Кухня'!AJ29:AJ32) -> 150 | G13: =MAX('Графік Кухня'!AJ29:AJ32) -> 156.5 | H13: =E13-Зміни!$C$19 -> -23.5
A14: КУХНЯ | B14: Кухар холодного цеху | C14: =COUNTA('Графік Кухня'!C38:C41) -> 4 | D14: =SUM('Графік Кухня'!AJ38:AJ41) -> 543 | E14: =IF(C14=0,0,D14/C14) -> 135.75 | F14: =MIN('Графік Кухня'!AJ38:AJ41) -> 135.5 | G14: =MAX('Графік Кухня'!AJ38:AJ41) -> 136.5 | H14: =E14-Зміни!$C$19 -> -40.25
A15: КУХНЯ | B15: Кондитер | C15: =COUNTA('Графік Кухня'!C47:C48) -> 2 | D15: =SUM('Графік Кухня'!AJ47:AJ48) -> 232.5 | E15: =IF(C15=0,0,D15/C15) -> 116.25 | F15: =MIN('Графік Кухня'!AJ47:AJ48) -> 112.5 | G15: =MAX('Графік Кухня'!AJ47:AJ48) -> 120 | H15: =E15-Зміни!$C$19 -> -59.75
A16: КУХНЯ | B16: Мийник | C16: =COUNTA('Графік Кухня'!C52:C55) -> 4 | D16: =SUM('Графік Кухня'!AJ52:AJ55) -> 523 | E16: =IF(C16=0,0,D16/C16) -> 130.75 | F16: =MIN('Графік Кухня'!AJ52:AJ55) -> 129 | G16: =MAX('Графік Кухня'!AJ52:AJ55) -> 132 | H16: =E16-Зміни!$C$19 -> -45.25
B17: Разом | C17: =SUM(C5:C16) -> 51 | D17: =SUM(D5:D16) -> 7416
A19: Фонд годин за днями тижня (середній день)
A20: День | B20: Рівень | C20: Зал, год | D20: Кухня, год | E20: Разом, год
A21: Пн | B21: =INDEX(Норми!$C$5:$I$5,1) -> Низький | C21: =SUMPRODUCT(('Графік Зал'!$D$5:$AH$5=A21)*'Графік Зал'!$D$74:$AH$74)/COUNTIF('Графік Зал'!$D$5:$AH$5,A21) -> 97.5 | D21: =SUMPRODUCT(('Графік Кухня'!$D$5:$AH$5=A21)*'Графік Кухня'!$D$61:$AH$61)/COUNTIF('Графік Кухня'!$D$5:$AH$5,A21) -> 82.5 | E21: =C21+D21 -> 180
A22: Вт | B22: =INDEX(Норми!$C$5:$I$5,2) -> Низький | C22: =SUMPRODUCT(('Графік Зал'!$D$5:$AH$5=A22)*'Графік Зал'!$D$74:$AH$74)/COUNTIF('Графік Зал'!$D$5:$AH$5,A22) -> 97.5 | D22: =SUMPRODUCT(('Графік Кухня'!$D$5:$AH$5=A22)*'Графік Кухня'!$D$61:$AH$61)/COUNTIF('Графік Кухня'!$D$5:$AH$5,A22) -> 82.5 | E22: =C22+D22 -> 180
A23: Ср | B23: =INDEX(Норми!$C$5:$I$5,3) -> Середній | C23: =SUMPRODUCT(('Графік Зал'!$D$5:$AH$5=A23)*'Графік Зал'!$D$74:$AH$74)/COUNTIF('Графік Зал'!$D$5:$AH$5,A23) -> 105 | D23: =SUMPRODUCT(('Графік Кухня'!$D$5:$AH$5=A23)*'Графік Кухня'!$D$61:$AH$61)/COUNTIF('Графік Кухня'!$D$5:$AH$5,A23) -> 82.5 | E23: =C23+D23 -> 187.5
A24: Чт | B24: =INDEX(Норми!$C$5:$I$5,4) -> Високий | C24: =SUMPRODUCT(('Графік Зал'!$D$5:$AH$5=A24)*'Графік Зал'!$D$74:$AH$74)/COUNTIF('Графік Зал'!$D$5:$AH$5,A24) -> 134.5 | D24: =SUMPRODUCT(('Графік Кухня'!$D$5:$AH$5=A24)*'Графік Кухня'!$D$61:$AH$61)/COUNTIF('Графік Кухня'!$D$5:$AH$5,A24) -> 90 | E24: =C24+D24 -> 224.5
A25: Пт | B25: =INDEX(Норми!$C$5:$I$5,5) -> Піковий | C25: =SUMPRODUCT(('Графік Зал'!$D$5:$AH$5=A25)*'Графік Зал'!$D$74:$AH$74)/COUNTIF('Графік Зал'!$D$5:$AH$5,A25) -> 181.5 | D25: =SUMPRODUCT(('Графік Кухня'!$D$5:$AH$5=A25)*'Графік Кухня'!$D$61:$AH$61)/COUNTIF('Графік Кухня'!$D$5:$AH$5,A25) -> 119.5 | E25: =C25+D25 -> 301
A26: Сб | B26: =INDEX(Норми!$C$5:$I$5,6) -> Піковий | C26: =SUMPRODUCT(('Графік Зал'!$D$5:$AH$5=A26)*'Графік Зал'!$D$74:$AH$74)/COUNTIF('Графік Зал'!$D$5:$AH$5,A26) -> 197 | D26: =SUMPRODUCT(('Графік Кухня'!$D$5:$AH$5=A26)*'Графік Кухня'!$D$61:$AH$61)/COUNTIF('Графік Кухня'!$D$5:$AH$5,A26) -> 127.5 | E26: =C26+D26 -> 324.5
A27: Нд | B27: =INDEX(Норми!$C$5:$I$5,7) -> Високий | C27: =SUMPRODUCT(('Графік Зал'!$D$5:$AH$5=A27)*'Графік Зал'!$D$74:$AH$74)/COUNTIF('Графік Зал'!$D$5:$AH$5,A27) -> 148 | D27: =SUMPRODUCT(('Графік Кухня'!$D$5:$AH$5=A27)*'Графік Кухня'!$D$61:$AH$61)/COUNTIF('Графік Кухня'!$D$5:$AH$5,A27) -> 96 | E27: =C27+D27 -> 244
A29: Як читати: фонд годин має зростати разом із рівнем завантаження. Якщо після отримання даних POS фактичні гості на годину персоналу суттєво різняться між днями — скоригуйте норми на аркуші «Норми».

Sheet Графік Зал
A1: BEEF — графік роботи: зал, жовтень 2026
A2: Р 09:30–17:00 · С 12:00–20:00 · В Пн–Вт 15:00–22:30, Ср–Сб 16:00–23:30, Нд 15:30–22:30 · П 17:30–23:30 (Чт–Сб) · порожньо — вихідний
A4: № | B4: Посада | C4: Співробітник | D4: 1 | E4: 2 | F4: 3 | G4: 4 | H4: 5 | I4: 6 | J4: 7 | K4: 8 | L4: 9 | M4: 10 | N4: 11 | O4: 12 | P4: 13 | Q4: 14 | R4: 15 | S4: 16 | T4: 17 | U4: 18 | V4: 19 | W4: 20 | X4: 21 | Y4: 22 | Z4: 23 | AA4: 24 | AB4: 25 | AC4: 26 | AD4: 27 | AE4: 28 | AF4: 29 | AG4: 30 | AH4: 31 | AI4: Змін | AJ4: Годин | AK4: Вихідних | AL4: Пт+Сб | AM4: Δ до норми, год
D5: Чт | E5: Пт | F5: Сб | G5: Нд | H5: Пн | I5: Вт | J5: Ср | K5: Чт | L5: Пт | M5: Сб | N5: Нд | O5: Пн | P5: Вт | Q5: Ср | R5: Чт | S5: Пт | T5: Сб | U5: Нд | V5: Пн | W5: Вт | X5: Ср | Y5: Чт | Z5: Пт | AA5: Сб | AB5: Нд | AC5: Пн | AD5: Вт | AE5: Ср | AF5: Чт | AG5: Пт | AH5: Сб
C6: Завантаження | D6: =LEFT(INDEX(Норми!$C$5:$I$5,MATCH(D$5,Норми!$C$4:$I$4,0)),3) -> Вис | E6: =LEFT(INDEX(Норми!$C$5:$I$5,MATCH(E$5,Норми!$C$4:$I$4,0)),3) -> Пік | F6: =LEFT(INDEX(Норми!$C$5:$I$5,MATCH(F$5,Норми!$C$4:$I$4,0)),3) -> Пік | G6: =LEFT(INDEX(Норми!$C$5:$I$5,MATCH(G$5,Норми!$C$4:$I$4,0)),3) -> Вис | H6: =LEFT(INDEX(Норми!$C$5:$I$5,MATCH(H$5,Норми!$C$4:$I$4,0)),3) -> Низ | I6: =LEFT(INDEX(Норми!$C$5:$I$5,MATCH(I$5,Норми!$C$4:$I$4,0)),3) -> Низ | J6: =LEFT(INDEX(Норми!$C$5:$I$5,MATCH(J$5,Норми!$C$4:$I$4,0)),3) -> Сер | K6: =LEFT(INDEX(Норми!$C$5:$I$5,MATCH(K$5,Норми!$C$4:$I$4,0)),3) -> Вис | ... AH6: =LEFT(INDEX(Норми!$C$5:$I$5,MATCH(AH$5,Норми!$C$4:$I$4,0)),3) -> Пік
C7: год. зміни Р | D7: =INDEX(Зміни!$C$13:$I$13,MATCH(D$5,Зміни!$C$12:$I$12,0)) -> 7.5 | E7: =INDEX(Зміни!$C$13:$I$13,MATCH(E$5,Зміни!$C$12:$I$12,0)) -> 7.5 | F7: =INDEX(Зміни!$C$13:$I$13,MATCH(F$5,Зміни!$C$12:$I$12,0)) -> 7.5 | G7: =INDEX(Зміни!$C$13:$I$13,MATCH(G$5,Зміни!$C$12:$I$12,0)) -> 7.5 | H7: =INDEX(Зміни!$C$13:$I$13,MATCH(H$5,Зміни!$C$12:$I$12,0)) -> 7.5 | I7: =INDEX(Зміни!$C$13:$I$13,MATCH(I$5,Зміни!$C$12:$I$12,0)) -> 7.5 | J7: =INDEX(Зміни!$C$13:$I$13,MATCH(J$5,Зміни!$C$12:$I$12,0)) -> 7.5 | K7: =INDEX(Зміни!$C$13:$I$13,MATCH(K$5,Зміни!$C$12:$I$12,0)) -> 7.5 | ... AH7: =INDEX(Зміни!$C$13:$I$13,MATCH(AH$5,Зміни!$C$12:$I$12,0)) -> 7.5
C8: год. зміни С | D8: =INDEX(Зміни!$C$14:$I$14,MATCH(D$5,Зміни!$C$12:$I$12,0)) -> 8 | E8: =INDEX(Зміни!$C$14:$I$14,MATCH(E$5,Зміни!$C$12:$I$12,0)) -> 8 | F8: =INDEX(Зміни!$C$14:$I$14,MATCH(F$5,Зміни!$C$12:$I$12,0)) -> 8 | G8: =INDEX(Зміни!$C$14:$I$14,MATCH(G$5,Зміни!$C$12:$I$12,0)) -> 8 | H8: =INDEX(Зміни!$C$14:$I$14,MATCH(H$5,Зміни!$C$12:$I$12,0)) -> 8 | I8: =INDEX(Зміни!$C$14:$I$14,MATCH(I$5,Зміни!$C$12:$I$12,0)) -> 8 | J8: =INDEX(Зміни!$C$14:$I$14,MATCH(J$5,Зміни!$C$12:$I$12,0)) -> 8 | K8: =INDEX(Зміни!$C$14:$I$14,MATCH(K$5,Зміни!$C$12:$I$12,0)) -> 8 | ... AH8: =INDEX(Зміни!$C$14:$I$14,MATCH(AH$5,Зміни!$C$12:$I$12,0)) -> 8
C9: год. зміни В | D9: =INDEX(Зміни!$C$15:$I$15,MATCH(D$5,Зміни!$C$12:$I$12,0)) -> 7.5 | E9: =INDEX(Зміни!$C$15:$I$15,MATCH(E$5,Зміни!$C$12:$I$12,0)) -> 7.5 | F9: =INDEX(Зміни!$C$15:$I$15,MATCH(F$5,Зміни!$C$12:$I$12,0)) -> 7.5 | G9: =INDEX(Зміни!$C$15:$I$15,MATCH(G$5,Зміни!$C$12:$I$12,0)) -> 7 | H9: =INDEX(Зміни!$C$15:$I$15,MATCH(H$5,Зміни!$C$12:$I$12,0)) -> 7.5 | I9: =INDEX(Зміни!$C$15:$I$15,MATCH(I$5,Зміни!$C$12:$I$12,0)) -> 7.5 | J9: =INDEX(Зміни!$C$15:$I$15,MATCH(J$5,Зміни!$C$12:$I$12,0)) -> 7.5 | K9: =INDEX(Зміни!$C$15:$I$15,MATCH(K$5,Зміни!$C$12:$I$12,0)) -> 7.5 | ... AH9: =INDEX(Зміни!$C$15:$I$15,MATCH(AH$5,Зміни!$C$12:$I$12,0)) -> 7.5
C10: год. зміни П | D10: =INDEX(Зміни!$C$16:$I$16,MATCH(D$5,Зміни!$C$12:$I$12,0)) -> 6 | E10: =INDEX(Зміни!$C$16:$I$16,MATCH(E$5,Зміни!$C$12:$I$12,0)) -> 6 | F10: =INDEX(Зміни!$C$16:$I$16,MATCH(F$5,Зміни!$C$12:$I$12,0)) -> 6 | G10: =INDEX(Зміни!$C$16:$I$16,MATCH(G$5,Зміни!$C$12:$I$12,0)) -> 6 | H10: =INDEX(Зміни!$C$16:$I$16,MATCH(H$5,Зміни!$C$12:$I$12,0)) -> 6 | I10: =INDEX(Зміни!$C$16:$I$16,MATCH(I$5,Зміни!$C$12:$I$12,0)) -> 6 | J10: =INDEX(Зміни!$C$16:$I$16,MATCH(J$5,Зміни!$C$12:$I$12,0)) -> 6 | K10: =INDEX(Зміни!$C$16:$I$16,MATCH(K$5,Зміни!$C$12:$I$12,0)) -> 6 | ... AH10: =INDEX(Зміни!$C$16:$I$16,MATCH(AH$5,Зміни!$C$12:$I$12,0)) -> 6
A12: МЕНЕДЖЕР ЗМІНИ
A13: 1 | B13: Менеджер зміни | C13: Менеджер зміни 1 | E13: Р | F13: Р | G13: Р | H13: В | I13: В | K13: Р | L13: Р | M13: Р | N13: Р | Q13: Р | R13: Р | S13: Р | V13: Р | W13: Р | X13: Р | Y13: Р | AB13: В | AC13: В | AD13: В | AE13: В | AH13: Р | AI13: =COUNTA(D13:AH13) -> 21 | AJ13: =SUMPRODUCT((D13:AH13="Р")*$D$7:$AH$7)+SUMPRODUCT((D13:AH13="С")*$D$8:$AH$8)+SUMPRODUCT((D13:AH13="В")*$D$9:$AH$9)+SUMPRODUCT((D13:AH13="П")*$D$10:$AH$10) -> 157 | AK13: =COLUMNS(D13:AH13)-AI13 -> 10 | AL13: =SUMPRODUCT((D13:AH13<>"")*(($D$5:$AH$5="Пт")+($D$5:$AH$5="Сб"))) -> 6 | AM13: =AJ13-Зміни!$C$19 -> -19
A14: 2 | B14: Менеджер зміни | C14: Менеджер зміни 2 | D14: Р | H14: Р | I14: Р | J14: Р | M14: В | N14: В | O14: В | P14: В | R14: В | S14: В | T14: В | U14: В | X14: В | Y14: В | Z14: В | AA14: В | AD14: Р | AE14: Р | AF14: В | AG14: В | AH14: В | AI14: =COUNTA(D14:AH14) -> 21 | AJ14: =SUMPRODUCT((D14:AH14="Р")*$D$7:$AH$7)+SUMPRODUCT((D14:AH14="С")*$D$8:$AH$8)+SUMPRODUCT((D14:AH14="В")*$D$9:$AH$9)+SUMPRODUCT((D14:AH14="П")*$D$10:$AH$10) -> 156.5 | AK14: =COLUMNS(D14:AH14)-AI14 -> 10 | AL14: =SUMPRODUCT((D14:AH14<>"")*(($D$5:$AH$5="Пт")+($D$5:$AH$5="Сб"))) -> 7 | AM14: =AJ14-Зміни!$C$19 -> -19.5
A15: 3 | B15: Менеджер зміни | C15: Менеджер зміни 3 | D15: В | E15: В | F15: В | G15: В | J15: В | K15: В | L15: В | O15: Р | P15: Р | Q15: В | T15: Р | U15: Р | V15: В | W15: В | Z15: Р | AA15: Р | AB15: Р | AC15: Р | AF15: Р | AG15: Р | AI15: =COUNTA(D15:AH15) -> 20 | AJ15: =SUMPRODUCT((D15:AH15="Р")*$D$7:$AH$7)+SUMPRODUCT((D15:AH15="С")*$D$8:$AH$8)+SUMPRODUCT((D15:AH15="В")*$D$9:$AH$9)+SUMPRODUCT((D15:AH15="П")*$D$10:$AH$10) -> 149.5 | AK15: =COLUMNS(D15:AH15)-AI15 -> 11 | AL15: =SUMPRODUCT((D15:AH15<>"")*(($D$5:$AH$5="Пт")+($D$5:$AH$5="Сб"))) -> 7 | AM15: =AJ15-Зміни!$C$19 -> -26.5
C16: Контроль Р (факт − норма) | D16: =COUNTIF(D$13:D$15,"Р")-INDEX(Норми!$C$12:$I$47,MATCH("Менеджер зміни|Р",Норми!$L$12:$L$47,0),MATCH(D$5,Норми!$C$11:$I$11,0)) -> 0 | E16: =COUNTIF(E$13:E$15,"Р")-INDEX(Норми!$C$12:$I$47,MATCH("Менеджер зміни|Р",Норми!$L$12:$L$47,0),MATCH(E$5,Норми!$C$11:$I$11,0)) -> 0 | F16: =COUNTIF(F$13:F$15,"Р")-INDEX(Норми!$C$12:$I$47,MATCH("Менеджер зміни|Р",Норми!$L$12:$L$47,0),MATCH(F$5,Норми!$C$11:$I$11,0)) -> 0 | G16: =COUNTIF(G$13:G$15,"Р")-INDEX(Норми!$C$12:$I$47,MATCH("Менеджер зміни|Р",Норми!$L$12:$L$47,0),MATCH(G$5,Норми!$C$11:$I$11,0)) -> 0 | H16: =COUNTIF(H$13:H$15,"Р")-INDEX(Норми!$C$12:$I$47,MATCH("Менеджер зміни|Р",Норми!$L$12:$L$47,0),MATCH(H$5,Норми!$C$11:$I$11,0)) -> 0 | I16: =COUNTIF(I$13:I$15,"Р")-INDEX(Норми!$C$12:$I$47,MATCH("Менеджер зміни|Р",Норми!$L$12:$L$47,0),MATCH(I$5,Норми!$C$11:$I$11,0)) -> 0 | J16: =COUNTIF(J$13:J$15,"Р")-INDEX(Норми!$C$12:$I$47,MATCH("Менеджер зміни|Р",Норми!$L$12:$L$47,0),MATCH(J$5,Норми!$C$11:$I$11,0)) -> 0 | K16: =COUNTIF(K$13:K$15,"Р")-INDEX(Норми!$C$12:$I$47,MATCH("Менеджер зміни|Р",Норми!$L$12:$L$47,0),MATCH(K$5,Норми!$C$11:$I$11,0)) -> 0 | ... AH16: =COUNTIF(AH$13:AH$15,"Р")-INDEX(Норми!$C$12:$I$47,MATCH("Менеджер зміни|Р",Норми!$L$12:$L$47,0),MATCH(AH$5,Норми!$C$11:$I$11,0)) -> 0
C17: Контроль В (факт − норма) | D17: =COUNTIF(D$13:D$15,"В")-INDEX(Норми!$C$12:$I$47,MATCH("Менеджер зміни|В",Норми!$L$12:$L$47,0),MATCH(D$5,Норми!$C$11:$I$11,0)) -> 0 | E17: =COUNTIF(E$13:E$15,"В")-INDEX(Норми!$C$12:$I$47,MATCH("Менеджер зміни|В",Норми!$L$12:$L$47,0),MATCH(E$5,Норми!$C$11:$I$11,0)) -> 0 | F17: =COUNTIF(F$13:F$15,"В")-INDEX(Норми!$C$12:$I$47,MATCH("Менеджер зміни|В",Норми!$L$12:$L$47,0),MATCH(F$5,Норми!$C$11:$I$11,0)) -> 0 | G17: =COUNTIF(G$13:G$15,"В")-INDEX(Норми!$C$12:$I$47,MATCH("Менеджер зміни|В",Норми!$L$12:$L$47,0),MATCH(G$5,Норми!$C$11:$I$11,0)) -> 0 | H17: =COUNTIF(H$13:H$15,"В")-INDEX(Норми!$C$12:$I$47,MATCH("Менеджер зміни|В",Норми!$L$12:$L$47,0),MATCH(H$5,Норми!$C$11:$I$11,0)) -> 0 | I17: =COUNTIF(I$13:I$15,"В")-INDEX(Норми!$C$12:$I$47,MATCH("Менеджер зміни|В",Норми!$L$12:$L$47,0),MATCH(I$5,Норми!$C$11:$I$11,0)) -> 0 | J17: =COUNTIF(J$13:J$15,"В")-INDEX(Норми!$C$12:$I$47,MATCH("Менеджер зміни|В",Норми!$L$12:$L$47,0),MATCH(J$5,Норми!$C$11:$I$11,0)) -> 0 | K17: =COUNTIF(K$13:K$15,"В")-INDEX(Норми!$C$12:$I$47,MATCH("Менеджер зміни|В",Норми!$L$12:$L$47,0),MATCH(K$5,Норми!$C$11:$I$11,0)) -> 0 | ... AH17: =COUNTIF(AH$13:AH$15,"В")-INDEX(Норми!$C$12:$I$47,MATCH("Менеджер зміни|В",Норми!$L$12:$L$47,0),MATCH(AH$5,Норми!$C$11:$I$11,0)) -> 0
A19: ХОСТЕС
A20: 4 | B20: Хостес | C20: Хостес 1 | E20: В | F20: В | G20: В | H20: В | I20: В | M20: Р | N20: Р | O20: Р | P20: Р | Q20: Р | U20: С | X20: Р | Y20: Р | Z20: П | AA20: П | AE20: Р | AF20: В | AG20: В | AH20: В | AI20: =COUNTA(D20:AH20) -> 19 | AJ20: =SUMPRODUCT((D20:AH20="Р")*$D$7:$AH$7)+SUMPRODUCT((D20:AH20="С")*$D$8:$AH$8)+SUMPRODUCT((D20:AH20="В")*$D$9:$AH$9)+SUMPRODUCT((D20:AH20="П")*$D$10:$AH$10) -> 139.5 | AK20: =COLUMNS(D20:AH20)-AI20 -> 12 | AL20: =SUMPRODUCT((D20:AH20<>"")*(($D$5:$AH$5="Пт")+($D$5:$AH$5="Сб"))) -> 7 | AM20: =AJ20-Зміни!$C$19 -> -36.5
A21: 5 | B21: Хостес | C21: Хостес 2 | D21: В | F21: Р | G21: Р | J21: В | K21: В | L21: П | Q21: В | R21: В | S21: П | T21: П | V21: Р | W21: Р | Z21: Р | AA21: Р | AB21: Р | AC21: Р | AD21: Р | AG21: Р | AH21: Р | AI21: =COUNTA(D21:AH21) -> 19 | AJ21: =SUMPRODUCT((D21:AH21="Р")*$D$7:$AH$7)+SUMPRODUCT((D21:AH21="С")*$D$8:$AH$8)+SUMPRODUCT((D21:AH21="В")*$D$9:$AH$9)+SUMPRODUCT((D21:AH21="П")*$D$10:$AH$10) -> 138 | AK21: =COLUMNS(D21:AH21)-AI21 -> 12 | AL21: =SUMPRODUCT((D21:AH21<>"")*(($D$5:$AH$5="Пт")+($D$5:$AH$5="Сб"))) -> 8 | AM21: =AJ21-Зміни!$C$19 -> -38
A22: 6 | B22: Хостес | C22: Хостес 3 | E22: Р | H22: Р | I22: Р | J22: Р | L22: В | M22: В | N22: В | O22: В | P22: В | S22: В | T22: В | U22: В | V22: В | X22: В | AB22: С | AC22: В | AF22: Р | AG22: П | AH22: П | AI22: =COUNTA(D22:AH22) -> 19 | AJ22: =SUMPRODUCT((D22:AH22="Р")*$D$7:$AH$7)+SUMPRODUCT((D22:AH22="С")*$D$8:$AH$8)+SUMPRODUCT((D22:AH22="В")*$D$9:$AH$9)+SUMPRODUCT((D22:AH22="П")*$D$10:$AH$10) -> 139 | AK22: =COLUMNS(D22:AH22)-AI22 -> 12 | AL22: =SUMPRODUCT((D22:AH22<>"")*(($D$5:$AH$5="Пт")+($D$5:$AH$5="Сб"))) -> 7 | AM22: =AJ22-Зміни!$C$19 -> -37
A23: 7 | B23: Хостес | C23: Хостес 4 | D23: Р | E23: П | F23: П | G23: С | K23: Р | L23: Р | M23: П | N23: С | R23: Р | S23: Р | T23: Р | U23: Р | W23: В | Y23: В | Z23: В | AA23: В | AB23: В | AD23: В | AE23: В | AI23: =COUNTA(D23:AH23) -> 19 | AJ23: =SUMPRODUCT((D23:AH23="Р")*$D$7:$AH$7)+SUMPRODUCT((D23:AH23="С")*$D$8:$AH$8)+SUMPRODUCT((D23:AH23="В")*$D$9:$AH$9)+SUMPRODUCT((D23:AH23="П")*$D$10:$AH$10) -> 138.5 | AK23: =COLUMNS(D23:AH23)-AI23 -> 12 | AL23: =SUMPRODUCT((D23:AH23<>"")*(($D$5:$AH$5="Пт")+($D$5:$AH$5="Сб"))) -> 8 | AM23: =AJ23-Зміни!$C$19 -> -37.5
C24: Контроль Р (факт − норма) | D24: =COUNTIF(D$20:D$23,"Р")-INDEX(Норми!$C$12:$I$47,MATCH("Хостес|Р",Норми!$L$12:$L$47,0),MATCH(D$5,Норми!$C$11:$I$11,0)) -> 0 | E24: =COUNTIF(E$20:E$23,"Р")-INDEX(Норми!$C$12:$I$47,MATCH("Хостес|Р",Норми!$L$12:$L$47,0),MATCH(E$5,Норми!$C$11:$I$11,0)) -> 0 | F24: =COUNTIF(F$20:F$23,"Р")-INDEX(Норми!$C$12:$I$47,MATCH("Хостес|Р",Норми!$L$12:$L$47,0),MATCH(F$5,Норми!$C$11:$I$11,0)) -> 0 | G24: =COUNTIF(G$20:G$23,"Р")-INDEX(Норми!$C$12:$I$47,MATCH("Хостес|Р",Норми!$L$12:$L$47,0),MATCH(G$5,Норми!$C$11:$I$11,0)) -> 0 | H24: =COUNTIF(H$20:H$23,"Р")-INDEX(Норми!$C$12:$I$47,MATCH("Хостес|Р",Норми!$L$12:$L$47,0),MATCH(H$5,Норми!$C$11:$I$11,0)) -> 0 | I24: =COUNTIF(I$20:I$23,"Р")-INDEX(Норми!$C$12:$I$47,MATCH("Хостес|Р",Норми!$L$12:$L$47,0),MATCH(I$5,Норми!$C$11:$I$11,0)) -> 0 | J24: =COUNTIF(J$20:J$23,"Р")-INDEX(Норми!$C$12:$I$47,MATCH("Хостес|Р",Норми!$L$12:$L$47,0),MATCH(J$5,Норми!$C$11:$I$11,0)) -> 0 | K24: =COUNTIF(K$20:K$23,"Р")-INDEX(Норми!$C$12:$I$47,MATCH("Хостес|Р",Норми!$L$12:$L$47,0),MATCH(K$5,Норми!$C$11:$I$11,0)) -> 0 | ... AH24: =COUNTIF(AH$20:AH$23,"Р")-INDEX(Норми!$C$12:$I$47,MATCH("Хостес|Р",Норми!$L$12:$L$47,0),MATCH(AH$5,Норми!$C$11:$I$11,0)) -> 0
C25: Контроль С (факт − норма) | D25: =COUNTIF(D$20:D$23,"С")-INDEX(Норми!$C$12:$I$47,MATCH("Хостес|С",Норми!$L$12:$L$47,0),MATCH(D$5,Норми!$C$11:$I$11,0)) -> 0 | E25: =COUNTIF(E$20:E$23,"С")-INDEX(Норми!$C$12:$I$47,MATCH("Хостес|С",Норми!$L$12:$L$47,0),MATCH(E$5,Норми!$C$11:$I$11,0)) -> 0 | F25: =COUNTIF(F$20:F$23,"С")-INDEX(Норми!$C$12:$I$47,MATCH("Хостес|С",Норми!$L$12:$L$47,0),MATCH(F$5,Норми!$C$11:$I$11,0)) -> 0 | G25: =COUNTIF(G$20:G$23,"С")-INDEX(Норми!$C$12:$I$47,MATCH("Хостес|С",Норми!$L$12:$L$47,0),MATCH(G$5,Норми!$C$11:$I$11,0)) -> 0 | H25: =COUNTIF(H$20:H$23,"С")-INDEX(Норми!$C$12:$I$47,MATCH("Хостес|С",Норми!$L$12:$L$47,0),MATCH(H$5,Норми!$C$11:$I$11,0)) -> 0 | I25: =COUNTIF(I$20:I$23,"С")-INDEX(Норми!$C$12:$I$47,MATCH("Хостес|С",Норми!$L$12:$L$47,0),MATCH(I$5,Норми!$C$11:$I$11,0)) -> 0 | J25: =COUNTIF(J$20:J$23,"С")-INDEX(Норми!$C$12:$I$47,MATCH("Хостес|С",Норми!$L$12:$L$47,0),MATCH(J$5,Норми!$C$11:$I$11,0)) -> 0 | K25: =COUNTIF(K$20:K$23,"С")-INDEX(Норми!$C$12:$I$47,MATCH("Хостес|С",Норми!$L$12:$L$47,0),MATCH(K$5,Норми!$C$11:$I$11,0)) -> 0 | ... AH25: =COUNTIF(AH$20:AH$23,"С")-INDEX(Норми!$C$12:$I$47,MATCH("Хостес|С",Норми!$L$12:$L$47,0),MATCH(AH$5,Норми!$C$11:$I$11,0)) -> 0
C26: Контроль В (факт − норма) | D26: =COUNTIF(D$20:D$23,"В")-INDEX(Норми!$C$12:$I$47,MATCH("Хостес|В",Норми!$L$12:$L$47,0),MATCH(D$5,Норми!$C$11:$I$11,0)) -> 0 | E26: =COUNTIF(E$20:E$23,"В")-INDEX(Норми!$C$12:$I$47,MATCH("Хостес|В",Норми!$L$12:$L$47,0),MATCH(E$5,Норми!$C$11:$I$11,0)) -> 0 | F26: =COUNTIF(F$20:F$23,"В")-INDEX(Норми!$C$12:$I$47,MATCH("Хостес|В",Норми!$L$12:$L$47,0),MATCH(F$5,Норми!$C$11:$I$11,0)) -> 0 | G26: =COUNTIF(G$20:G$23,"В")-INDEX(Норми!$C$12:$I$47,MATCH("Хостес|В",Норми!$L$12:$L$47,0),MATCH(G$5,Норми!$C$11:$I$11,0)) -> 0 | H26: =COUNTIF(H$20:H$23,"В")-INDEX(Норми!$C$12:$I$47,MATCH("Хостес|В",Норми!$L$12:$L$47,0),MATCH(H$5,Норми!$C$11:$I$11,0)) -> 0 | I26: =COUNTIF(I$20:I$23,"В")-INDEX(Норми!$C$12:$I$47,MATCH("Хостес|В",Норми!$L$12:$L$47,0),MATCH(I$5,Норми!$C$11:$I$11,0)) -> 0 | J26: =COUNTIF(J$20:J$23,"В")-INDEX(Норми!$C$12:$I$47,MATCH("Хостес|В",Норми!$L$12:$L$47,0),MATCH(J$5,Норми!$C$11:$I$11,0)) -> 0 | K26: =COUNTIF(K$20:K$23,"В")-INDEX(Норми!$C$12:$I$47,MATCH("Хостес|В",Норми!$L$12:$L$47,0),MATCH(K$5,Норми!$C$11:$I$11,0)) -> 0 | ... AH26: =COUNTIF(AH$20:AH$23,"В")-INDEX(Норми!$C$12:$I$47,MATCH("Хостес|В",Норми!$L$12:$L$47,0),MATCH(AH$5,Норми!$C$11:$I$11,0)) -> 0
C27: Контроль П (факт − норма) | D27: =COUNTIF(D$20:D$23,"П")-INDEX(Норми!$C$12:$I$47,MATCH("Хостес|П",Норми!$L$12:$L$47,0),MATCH(D$5,Норми!$C$11:$I$11,0)) -> 0 | E27: =COUNTIF(E$20:E$23,"П")-INDEX(Норми!$C$12:$I$47,MATCH("Хостес|П",Норми!$L$12:$L$47,0),MATCH(E$5,Норми!$C$11:$I$11,0)) -> 0 | F27: =COUNTIF(F$20:F$23,"П")-INDEX(Норми!$C$12:$I$47,MATCH("Хостес|П",Норми!$L$12:$L$47,0),MATCH(F$5,Норми!$C$11:$I$11,0)) -> 0 | G27: =COUNTIF(G$20:G$23,"П")-INDEX(Норми!$C$12:$I$47,MATCH("Хостес|П",Норми!$L$12:$L$47,0),MATCH(G$5,Норми!$C$11:$I$11,0)) -> 0 | H27: =COUNTIF(H$20:H$23,"П")-INDEX(Норми!$C$12:$I$47,MATCH("Хостес|П",Норми!$L$12:$L$47,0),MATCH(H$5,Норми!$C$11:$I$11,0)) -> 0 | I27: =COUNTIF(I$20:I$23,"П")-INDEX(Норми!$C$12:$I$47,MATCH("Хостес|П",Норми!$L$12:$L$47,0),MATCH(I$5,Норми!$C$11:$I$11,0)) -> 0 | J27: =COUNTIF(J$20:J$23,"П")-INDEX(Норми!$C$12:$I$47,MATCH("Хостес|П",Норми!$L$12:$L$47,0),MATCH(J$5,Норми!$C$11:$I$11,0)) -> 0 | K27: =COUNTIF(K$20:K$23,"П")-INDEX(Норми!$C$12:$I$47,MATCH("Хостес|П",Норми!$L$12:$L$47,0),MATCH(K$5,Норми!$C$11:$I$11,0)) -> 0 | ... AH27: =COUNTIF(AH$20:AH$23,"П")-INDEX(Норми!$C$12:$I$47,MATCH("Хостес|П",Норми!$L$12:$L$47,0),MATCH(AH$5,Норми!$C$11:$I$11,0)) -> 0
A29: ОФІЦІАНТ
A30: 8 | B30: Офіціант | C30: Офіціант 1 | D30: П | E30: В | F30: В | G30: В | J30: Р | L30: В | M30: В | N30: В | P30: В | Q30: В | S30: Р | T30: Р | U30: Р | V30: Р | Z30: С | AA30: С | AB30: С | AE30: Р | AF30: Р | AH30: С | AI30: =COUNTA(D30:AH30) -> 20 | AJ30: =SUMPRODUCT((D30:AH30="Р")*$D$7:$AH$7)+SUMPRODUCT((D30:AH30="С")*$D$8:$AH$8)+SUMPRODUCT((D30:AH30="В")*$D$9:$AH$9)+SUMPRODUCT((D30:AH30="П")*$D$10:$AH$10) -> 149.5 | AK30: =COLUMNS(D30:AH30)-AI30 -> 11 | AL30: =SUMPRODUCT((D30:AH30<>"")*(($D$5:$AH$5="Пт")+($D$5:$AH$5="Сб"))) -> 9 | AM30: =AJ30-Зміни!$C$19 -> -26.5
A31: 9 | B31: Офіціант | C31: Офіціант 2 | D31: В | E31: В | F31: В | G31: В | I31: В | J31: В | K31: В | L31: П | M31: П | O31: В | R31: С | S31: П | T31: С | W31: Р | X31: Р | AA31: Р | AB31: Р | AE31: Р | AF31: Р | AG31: П | AH31: П | AI31: =COUNTA(D31:AH31) -> 21 | AJ31: =SUMPRODUCT((D31:AH31="Р")*$D$7:$AH$7)+SUMPRODUCT((D31:AH31="С")*$D$8:$AH$8)+SUMPRODUCT((D31:AH31="В")*$D$9:$AH$9)+SUMPRODUCT((D31:AH31="П")*$D$10:$AH$10) -> 150.5 | AK31: =COLUMNS(D31:AH31)-AI31 -> 10 | AL31: =SUMPRODUCT((D31:AH31<>"")*(($D$5:$AH$5="Пт")+($D$5:$AH$5="Сб"))) -> 9 | AM31: =AJ31-Зміни!$C$19 -> -25.5
A32: 10 | B32: Офіціант | C32: Офіціант 3 | E32: Р | F32: Р | G32: Р | H32: Р | K32: С | L32: В | M32: В | O32: В | P32: В | Q32: В | S32: В | T32: В | U32: В | V32: В | Y32: В | Z32: В | AA32: В | AC32: В | AG32: Р | AH32: Р | AI32: =COUNTA(D32:AH32) -> 20 | AJ32: =SUMPRODUCT((D32:AH32="Р")*$D$7:$AH$7)+SUMPRODUCT((D32:AH32="С")*$D$8:$AH$8)+SUMPRODUCT((D32:AH32="В")*$D$9:$AH$9)+SUMPRODUCT((D32:AH32="П")*$D$10:$AH$10) -> 150 | AK32: =COLUMNS(D32:AH32)-AI32 -> 11 | AL32: =SUMPRODUCT((D32:AH32<>"")*(($D$5:$AH$5="Пт")+($D$5:$AH$5="Сб"))) -> 10 | AM32: =AJ32-Зміни!$C$19 -> -26
A33: 11 | B33: Офіціант | C33: Офіціант 4 | D33: В | E33: В | F33: С | G33: С | M33: Р | N33: Р | O33: Р | P33: Р | R33: Р | S33: Р | T33: П | W33: В | X33: В | Z33: Р | AA33: Р | AB33: Р | AC33: Р | AF33: С | AG33: С | AH33: С | AI33: =COUNTA(D33:AH33) -> 20 | AJ33: =SUMPRODUCT((D33:AH33="Р")*$D$7:$AH$7)+SUMPRODUCT((D33:AH33="С")*$D$8:$AH$8)+SUMPRODUCT((D33:AH33="В")*$D$9:$AH$9)+SUMPRODUCT((D33:AH33="П")*$D$10:$AH$10) -> 151 | AK33: =COLUMNS(D33:AH33)-AI33 -> 11 | AL33: =SUMPRODUCT((D33:AH33<>"")*(($D$5:$AH$5="Пт")+($D$5:$AH$5="Сб"))) -> 9 | AM33: =AJ33-Зміни!$C$19 -> -25
A34: 12 | B34: Офіціант | C34: Офіціант 5 | D34: С | E34: П | F34: П | H34: В | K34: Р | L34: Р | M34: С | N34: С | R34: Р | S34: С | T34: С | U34: С | X34: В | Y34: В | Z34: В | AA34: В | AB34: В | AD34: Р | AG34: Р | AH34: Р | AI34: =COUNTA(D34:AH34) -> 20 | AJ34: =SUMPRODUCT((D34:AH34="Р")*$D$7:$AH$7)+SUMPRODUCT((D34:AH34="С")*$D$8:$AH$8)+SUMPRODUCT((D34:AH34="В")*$D$9:$AH$9)+SUMPRODUCT((D34:AH34="П")*$D$10:$AH$10) -> 149.5 | AK34: =COLUMNS(D34:AH34)-AI34 -> 11 | AL34: =SUMPRODUCT((D34:AH34<>"")*(($D$5:$AH$5="Пт")+($D$5:$AH$5="Сб"))) -> 10 | AM34: =AJ34-Зміни!$C$19 -> -26.5
A35: 13 | B35: Офіціант | C35: Офіціант 6 | E35: С | F35: С | G35: С | K35: Р | L35: Р | M35: Р | N35: Р | Q35: Р | S35: Р | T35: Р | U35: Р | V35: Р | W35: Р | Y35: П | Z35: П | AA35: П | AD35: В | AE35: В | AF35: П | AG35: П | AH35: П | AI35: =COUNTA(D35:AH35) -> 21 | AJ35: =SUMPRODUCT((D35:AH35="Р")*$D$7:$AH$7)+SUMPRODUCT((D35:AH35="С")*$D$8:$AH$8)+SUMPRODUCT((D35:AH35="В")*$D$9:$AH$9)+SUMPRODUCT((D35:AH35="П")*$D$10:$AH$10) -> 150 | AK35: =COLUMNS(D35:AH35)-AI35 -> 10 | AL35: =SUMPRODUCT((D35:AH35<>"")*(($D$5:$AH$5="Пт")+($D$5:$AH$5="Сб"))) -> 10 | AM35: =AJ35-Зміни!$C$19 -> -26
A36: 14 | B36: Офіціант | C36: Офіціант 7 | D36: В | E36: В | F36: В | I36: В | J36: В | K36: В | L36: В | M36: В | P36: Р | T36: Р | U36: Р | V36: В | X36: В | Z36: Р | AA36: Р | AB36: Р | AC36: Р | AD36: Р | AG36: Р | AH36: Р | AI36: =COUNTA(D36:AH36) -> 20 | AJ36: =SUMPRODUCT((D36:AH36="Р")*$D$7:$AH$7)+SUMPRODUCT((D36:AH36="С")*$D$8:$AH$8)+SUMPRODUCT((D36:AH36="В")*$D$9:$AH$9)+SUMPRODUCT((D36:AH36="П")*$D$10:$AH$10) -> 150 | AK36: =COLUMNS(D36:AH36)-AI36 -> 11 | AL36: =SUMPRODUCT((D36:AH36<>"")*(($D$5:$AH$5="Пт")+($D$5:$AH$5="Сб"))) -> 9 | AM36: =AJ36-Зміни!$C$19 -> -26
A37: 15 | B37: Офіціант | C37: Офіціант 8 | D37: Р | E37: Р | F37: В | G37: В | I37: Р | L37: С | M37: С | N37: С | Q37: В | R37: В | S37: В | T37: В | W37: В | Y37: В | Z37: В | AA37: В | AB37: В | AC37: В | AG37: В | AH37: В | AI37: =COUNTA(D37:AH37) -> 20 | AJ37: =SUMPRODUCT((D37:AH37="Р")*$D$7:$AH$7)+SUMPRODUCT((D37:AH37="С")*$D$8:$AH$8)+SUMPRODUCT((D37:AH37="В")*$D$9:$AH$9)+SUMPRODUCT((D37:AH37="П")*$D$10:$AH$10) -> 150.5 | AK37: =COLUMNS(D37:AH37)-AI37 -> 11 | AL37: =SUMPRODUCT((D37:AH37<>"")*(($D$5:$AH$5="Пт")+($D$5:$AH$5="Сб"))) -> 10 | AM37: =AJ37-Зміни!$C$19 -> -25.5
A38: 16 | B38: Офіціант | C38: Офіціант 9 | D38: Р | E38: Р | F38: Р | G38: Р | H38: Р | K38: П | L38: П | M38: П | N38: В | R38: В | S38: В | T38: В | U38: С | Y38: Р | Z38: Р | AA38: П | AD38: В | AE38: В | AF38: В | AG38: В | AH38: В | AI38: =COUNTA(D38:AH38) -> 21 | AJ38: =SUMPRODUCT((D38:AH38="Р")*$D$7:$AH$7)+SUMPRODUCT((D38:AH38="С")*$D$8:$AH$8)+SUMPRODUCT((D38:AH38="В")*$D$9:$AH$9)+SUMPRODUCT((D38:AH38="П")*$D$10:$AH$10) -> 151.5 | AK38: =COLUMNS(D38:AH38)-AI38 -> 10 | AL38: =SUMPRODUCT((D38:AH38<>"")*(($D$5:$AH$5="Пт")+($D$5:$AH$5="Сб"))) -> 10 | AM38: =AJ38-Зміни!$C$19 -> -24.5
A39: 17 | B39: Офіціант | C39: Офіціант 10 | F39: Р | G39: Р | I39: Р | J39: Р | L39: Р | M39: Р | N39: Р | O39: Р | R39: В | S39: В | T39: В | U39: В | X39: Р | Y39: Р | Z39: П | AA39: С | AB39: С | AF39: В | AG39: В | AH39: В | AI39: =COUNTA(D39:AH39) -> 20 | AJ39: =SUMPRODUCT((D39:AH39="Р")*$D$7:$AH$7)+SUMPRODUCT((D39:AH39="С")*$D$8:$AH$8)+SUMPRODUCT((D39:AH39="В")*$D$9:$AH$9)+SUMPRODUCT((D39:AH39="П")*$D$10:$AH$10) -> 149 | AK39: =COLUMNS(D39:AH39)-AI39 -> 11 | AL39: =SUMPRODUCT((D39:AH39<>"")*(($D$5:$AH$5="Пт")+($D$5:$AH$5="Сб"))) -> 9 | AM39: =AJ39-Зміни!$C$19 -> -27
A40: 18 | B40: Офіціант | C40: Офіціант 11 | E40: П | F40: П | H40: В | J40: В | K40: В | L40: В | M40: В | N40: В | Q40: Р | R40: П | S40: П | T40: П | U40: В | Y40: С | Z40: В | AA40: В | AB40: В | AE40: В | AF40: В | AG40: В | AH40: В | AI40: =COUNTA(D40:AH40) -> 21 | AJ40: =SUMPRODUCT((D40:AH40="Р")*$D$7:$AH$7)+SUMPRODUCT((D40:AH40="С")*$D$8:$AH$8)+SUMPRODUCT((D40:AH40="В")*$D$9:$AH$9)+SUMPRODUCT((D40:AH40="П")*$D$10:$AH$10) -> 149 | AK40: =COLUMNS(D40:AH40)-AI40 -> 10 | AL40: =SUMPRODUCT((D40:AH40<>"")*(($D$5:$AH$5="Пт")+($D$5:$AH$5="Сб"))) -> 10 | AM40: =AJ40-Зміни!$C$19 -> -27
C41: Контроль Р (факт − норма) | D41: =COUNTIF(D$30:D$40,"Р")-INDEX(Норми!$C$12:$I$47,MATCH("Офіціант|Р",Норми!$L$12:$L$47,0),MATCH(D$5,Норми!$C$11:$I$11,0)) -> 0 | E41: =COUNTIF(E$30:E$40,"Р")-INDEX(Норми!$C$12:$I$47,MATCH("Офіціант|Р",Норми!$L$12:$L$47,0),MATCH(E$5,Норми!$C$11:$I$11,0)) -> 0 | F41: =COUNTIF(F$30:F$40,"Р")-INDEX(Норми!$C$12:$I$47,MATCH("Офіціант|Р",Норми!$L$12:$L$47,0),MATCH(F$5,Норми!$C$11:$I$11,0)) -> 0 | G41: =COUNTIF(G$30:G$40,"Р")-INDEX(Норми!$C$12:$I$47,MATCH("Офіціант|Р",Норми!$L$12:$L$47,0),MATCH(G$5,Норми!$C$11:$I$11,0)) -> 0 | H41: =COUNTIF(H$30:H$40,"Р")-INDEX(Норми!$C$12:$I$47,MATCH("Офіціант|Р",Норми!$L$12:$L$47,0),MATCH(H$5,Норми!$C$11:$I$11,0)) -> 0 | I41: =COUNTIF(I$30:I$40,"Р")-INDEX(Норми!$C$12:$I$47,MATCH("Офіціант|Р",Норми!$L$12:$L$47,0),MATCH(I$5,Норми!$C$11:$I$11,0)) -> 0 | J41: =COUNTIF(J$30:J$40,"Р")-INDEX(Норми!$C$12:$I$47,MATCH("Офіціант|Р",Норми!$L$12:$L$47,0),MATCH(J$5,Норми!$C$11:$I$11,0)) -> 0 | K41: =COUNTIF(K$30:K$40,"Р")-INDEX(Норми!$C$12:$I$47,MATCH("Офіціант|Р",Норми!$L$12:$L$47,0),MATCH(K$5,Норми!$C$11:$I$11,0)) -> 0 | ... AH41: =COUNTIF(AH$30:AH$40,"Р")-INDEX(Норми!$C$12:$I$47,MATCH("Офіціант|Р",Норми!$L$12:$L$47,0),MATCH(AH$5,Норми!$C$11:$I$11,0)) -> 0
C42: Контроль С (факт − норма) | D42: =COUNTIF(D$30:D$40,"С")-INDEX(Норми!$C$12:$I$47,MATCH("Офіціант|С",Норми!$L$12:$L$47,0),MATCH(D$5,Норми!$C$11:$I$11,0)) -> 0 | E42: =COUNTIF(E$30:E$40,"С")-INDEX(Норми!$C$12:$I$47,MATCH("Офіціант|С",Норми!$L$12:$L$47,0),MATCH(E$5,Норми!$C$11:$I$11,0)) -> 0 | F42: =COUNTIF(F$30:F$40,"С")-INDEX(Норми!$C$12:$I$47,MATCH("Офіціант|С",Норми!$L$12:$L$47,0),MATCH(F$5,Норми!$C$11:$I$11,0)) -> 0 | G42: =COUNTIF(G$30:G$40,"С")-INDEX(Норми!$C$12:$I$47,MATCH("Офіціант|С",Норми!$L$12:$L$47,0),MATCH(G$5,Норми!$C$11:$I$11,0)) -> 0 | H42: =COUNTIF(H$30:H$40,"С")-INDEX(Норми!$C$12:$I$47,MATCH("Офіціант|С",Норми!$L$12:$L$47,0),MATCH(H$5,Норми!$C$11:$I$11,0)) -> 0 | I42: =COUNTIF(I$30:I$40,"С")-INDEX(Норми!$C$12:$I$47,MATCH("Офіціант|С",Норми!$L$12:$L$47,0),MATCH(I$5,Норми!$C$11:$I$11,0)) -> 0 | J42: =COUNTIF(J$30:J$40,"С")-INDEX(Норми!$C$12:$I$47,MATCH("Офіціант|С",Норми!$L$12:$L$47,0),MATCH(J$5,Норми!$C$11:$I$11,0)) -> 0 | K42: =COUNTIF(K$30:K$40,"С")-INDEX(Норми!$C$12:$I$47,MATCH("Офіціант|С",Норми!$L$12:$L$47,0),MATCH(K$5,Норми!$C$11:$I$11,0)) -> 0 | ... AH42: =COUNTIF(AH$30:AH$40,"С")-INDEX(Норми!$C$12:$I$47,MATCH("Офіціант|С",Норми!$L$12:$L$47,0),MATCH(AH$5,Норми!$C$11:$I$11,0)) -> 0
C43: Контроль В (факт − норма) | D43: =COUNTIF(D$30:D$40,"В")-INDEX(Норми!$C$12:$I$47,MATCH("Офіціант|В",Норми!$L$12:$L$47,0),MATCH(D$5,Норми!$C$11:$I$11,0)) -> 0 | E43: =COUNTIF(E$30:E$40,"В")-INDEX(Норми!$C$12:$I$47,MATCH("Офіціант|В",Норми!$L$12:$L$47,0),MATCH(E$5,Норми!$C$11:$I$11,0)) -> 0 | F43: =COUNTIF(F$30:F$40,"В")-INDEX(Норми!$C$12:$I$47,MATCH("Офіціант|В",Норми!$L$12:$L$47,0),MATCH(F$5,Норми!$C$11:$I$11,0)) -> 0 | G43: =COUNTIF(G$30:G$40,"В")-INDEX(Норми!$C$12:$I$47,MATCH("Офіціант|В",Норми!$L$12:$L$47,0),MATCH(G$5,Норми!$C$11:$I$11,0)) -> 0 | H43: =COUNTIF(H$30:H$40,"В")-INDEX(Норми!$C$12:$I$47,MATCH("Офіціант|В",Норми!$L$12:$L$47,0),MATCH(H$5,Норми!$C$11:$I$11,0)) -> 0 | I43: =COUNTIF(I$30:I$40,"В")-INDEX(Норми!$C$12:$I$47,MATCH("Офіціант|В",Норми!$L$12:$L$47,0),MATCH(I$5,Норми!$C$11:$I$11,0)) -> 0 | J43: =COUNTIF(J$30:J$40,"В")-INDEX(Норми!$C$12:$I$47,MATCH("Офіціант|В",Норми!$L$12:$L$47,0),MATCH(J$5,Норми!$C$11:$I$11,0)) -> 0 | K43: =COUNTIF(K$30:K$40,"В")-INDEX(Норми!$C$12:$I$47,MATCH("Офіціант|В",Норми!$L$12:$L$47,0),MATCH(K$5,Норми!$C$11:$I$11,0)) -> 0 | ... AH43: =COUNTIF(AH$30:AH$40,"В")-INDEX(Норми!$C$12:$I$47,MATCH("Офіціант|В",Норми!$L$12:$L$47,0),MATCH(AH$5,Норми!$C$11:$I$11,0)) -> 0
C44: Контроль П (факт − норма) | D44: =COUNTIF(D$30:D$40,"П")-INDEX(Норми!$C$12:$I$47,MATCH("Офіціант|П",Норми!$L$12:$L$47,0),MATCH(D$5,Норми!$C$11:$I$11,0)) -> 0 | E44: =COUNTIF(E$30:E$40,"П")-INDEX(Норми!$C$12:$I$47,MATCH("Офіціант|П",Норми!$L$12:$L$47,0),MATCH(E$5,Норми!$C$11:$I$11,0)) -> 0 | F44: =COUNTIF(F$30:F$40,"П")-INDEX(Норми!$C$12:$I$47,MATCH("Офіціант|П",Норми!$L$12:$L$47,0),MATCH(F$5,Норми!$C$11:$I$11,0)) -> 0 | G44: =COUNTIF(G$30:G$40,"П")-INDEX(Норми!$C$12:$I$47,MATCH("Офіціант|П",Норми!$L$12:$L$47,0),MATCH(G$5,Норми!$C$11:$I$11,0)) -> 0 | H44: =COUNTIF(H$30:H$40,"П")-INDEX(Норми!$C$12:$I$47,MATCH("Офіціант|П",Норми!$L$12:$L$47,0),MATCH(H$5,Норми!$C$11:$I$11,0)) -> 0 | I44: =COUNTIF(I$30:I$40,"П")-INDEX(Норми!$C$12:$I$47,MATCH("Офіціант|П",Норми!$L$12:$L$47,0),MATCH(I$5,Норми!$C$11:$I$11,0)) -> 0 | J44: =COUNTIF(J$30:J$40,"П")-INDEX(Норми!$C$12:$I$47,MATCH("Офіціант|П",Норми!$L$12:$L$47,0),MATCH(J$5,Норми!$C$11:$I$11,0)) -> 0 | K44: =COUNTIF(K$30:K$40,"П")-INDEX(Норми!$C$12:$I$47,MATCH("Офіціант|П",Норми!$L$12:$L$47,0),MATCH(K$5,Норми!$C$11:$I$11,0)) -> 0 | ... AH44: =COUNTIF(AH$30:AH$40,"П")-INDEX(Норми!$C$12:$I$47,MATCH("Офіціант|П",Норми!$L$12:$L$47,0),MATCH(AH$5,Норми!$C$11:$I$11,0)) -> 0
...

Sheet Графік Кухня
A1: BEEF — графік роботи: кухня, жовтень 2026
A2: Р 09:30–17:00 · С 12:00–20:00 · В Пн–Вт 15:00–22:30, Ср–Сб 16:00–23:30, Нд 15:30–22:30 · П 17:30–23:30 (Чт–Сб) · порожньо — вихідний
A4: № | B4: Посада | C4: Співробітник | D4: 1 | E4: 2 | F4: 3 | G4: 4 | H4: 5 | I4: 6 | J4: 7 | K4: 8 | L4: 9 | M4: 10 | N4: 11 | O4: 12 | P4: 13 | Q4: 14 | R4: 15 | S4: 16 | T4: 17 | U4: 18 | V4: 19 | W4: 20 | X4: 21 | Y4: 22 | Z4: 23 | AA4: 24 | AB4: 25 | AC4: 26 | AD4: 27 | AE4: 28 | AF4: 29 | AG4: 30 | AH4: 31 | AI4: Змін | AJ4: Годин | AK4: Вихідних | AL4: Пт+Сб | AM4: Δ до норми, год
D5: Чт | E5: Пт | F5: Сб | G5: Нд | H5: Пн | I5: Вт | J5: Ср | K5: Чт | L5: Пт | M5: Сб | N5: Нд | O5: Пн | P5: Вт | Q5: Ср | R5: Чт | S5: Пт | T5: Сб | U5: Нд | V5: Пн | W5: Вт | X5: Ср | Y5: Чт | Z5: Пт | AA5: Сб | AB5: Нд | AC5: Пн | AD5: Вт | AE5: Ср | AF5: Чт | AG5: Пт | AH5: Сб
C6: Завантаження | D6: =LEFT(INDEX(Норми!$C$5:$I$5,MATCH(D$5,Норми!$C$4:$I$4,0)),3) -> Вис | E6: =LEFT(INDEX(Норми!$C$5:$I$5,MATCH(E$5,Норми!$C$4:$I$4,0)),3) -> Пік | F6: =LEFT(INDEX(Норми!$C$5:$I$5,MATCH(F$5,Норми!$C$4:$I$4,0)),3) -> Пік | G6: =LEFT(INDEX(Норми!$C$5:$I$5,MATCH(G$5,Норми!$C$4:$I$4,0)),3) -> Вис | H6: =LEFT(INDEX(Норми!$C$5:$I$5,MATCH(H$5,Норми!$C$4:$I$4,0)),3) -> Низ | I6: =LEFT(INDEX(Норми!$C$5:$I$5,MATCH(I$5,Норми!$C$4:$I$4,0)),3) -> Низ | J6: =LEFT(INDEX(Норми!$C$5:$I$5,MATCH(J$5,Норми!$C$4:$I$4,0)),3) -> Сер | K6: =LEFT(INDEX(Норми!$C$5:$I$5,MATCH(K$5,Норми!$C$4:$I$4,0)),3) -> Вис | ... AH6: =LEFT(INDEX(Норми!$C$5:$I$5,MATCH(AH$5,Норми!$C$4:$I$4,0)),3) -> Пік
C7: год. зміни Р | D7: =INDEX(Зміни!$C$13:$I$13,MATCH(D$5,Зміни!$C$12:$I$12,0)) -> 7.5 | E7: =INDEX(Зміни!$C$13:$I$13,MATCH(E$5,Зміни!$C$12:$I$12,0)) -> 7.5 | F7: =INDEX(Зміни!$C$13:$I$13,MATCH(F$5,Зміни!$C$12:$I$12,0)) -> 7.5 | G7: =INDEX(Зміни!$C$13:$I$13,MATCH(G$5,Зміни!$C$12:$I$12,0)) -> 7.5 | H7: =INDEX(Зміни!$C$13:$I$13,MATCH(H$5,Зміни!$C$12:$I$12,0)) -> 7.5 | I7: =INDEX(Зміни!$C$13:$I$13,MATCH(I$5,Зміни!$C$12:$I$12,0)) -> 7.5 | J7: =INDEX(Зміни!$C$13:$I$13,MATCH(J$5,Зміни!$C$12:$I$12,0)) -> 7.5 | K7: =INDEX(Зміни!$C$13:$I$13,MATCH(K$5,Зміни!$C$12:$I$12,0)) -> 7.5 | ... AH7: =INDEX(Зміни!$C$13:$I$13,MATCH(AH$5,Зміни!$C$12:$I$12,0)) -> 7.5
C8: год. зміни С | D8: =INDEX(Зміни!$C$14:$I$14,MATCH(D$5,Зміни!$C$12:$I$12,0)) -> 8 | E8: =INDEX(Зміни!$C$14:$I$14,MATCH(E$5,Зміни!$C$12:$I$12,0)) -> 8 | F8: =INDEX(Зміни!$C$14:$I$14,MATCH(F$5,Зміни!$C$12:$I$12,0)) -> 8 | G8: =INDEX(Зміни!$C$14:$I$14,MATCH(G$5,Зміни!$C$12:$I$12,0)) -> 8 | H8: =INDEX(Зміни!$C$14:$I$14,MATCH(H$5,Зміни!$C$12:$I$12,0)) -> 8 | I8: =INDEX(Зміни!$C$14:$I$14,MATCH(I$5,Зміни!$C$12:$I$12,0)) -> 8 | J8: =INDEX(Зміни!$C$14:$I$14,MATCH(J$5,Зміни!$C$12:$I$12,0)) -> 8 | K8: =INDEX(Зміни!$C$14:$I$14,MATCH(K$5,Зміни!$C$12:$I$12,0)) -> 8 | ... AH8: =INDEX(Зміни!$C$14:$I$14,MATCH(AH$5,Зміни!$C$12:$I$12,0)) -> 8
C9: год. зміни В | D9: =INDEX(Зміни!$C$15:$I$15,MATCH(D$5,Зміни!$C$12:$I$12,0)) -> 7.5 | E9: =INDEX(Зміни!$C$15:$I$15,MATCH(E$5,Зміни!$C$12:$I$12,0)) -> 7.5 | F9: =INDEX(Зміни!$C$15:$I$15,MATCH(F$5,Зміни!$C$12:$I$12,0)) -> 7.5 | G9: =INDEX(Зміни!$C$15:$I$15,MATCH(G$5,Зміни!$C$12:$I$12,0)) -> 7 | H9: =INDEX(Зміни!$C$15:$I$15,MATCH(H$5,Зміни!$C$12:$I$12,0)) -> 7.5 | I9: =INDEX(Зміни!$C$15:$I$15,MATCH(I$5,Зміни!$C$12:$I$12,0)) -> 7.5 | J9: =INDEX(Зміни!$C$15:$I$15,MATCH(J$5,Зміни!$C$12:$I$12,0)) -> 7.5 | K9: =INDEX(Зміни!$C$15:$I$15,MATCH(K$5,Зміни!$C$12:$I$12,0)) -> 7.5 | ... AH9: =INDEX(Зміни!$C$15:$I$15,MATCH(AH$5,Зміни!$C$12:$I$12,0)) -> 7.5
C10: год. зміни П | D10: =INDEX(Зміни!$C$16:$I$16,MATCH(D$5,Зміни!$C$12:$I$12,0)) -> 6 | E10: =INDEX(Зміни!$C$16:$I$16,MATCH(E$5,Зміни!$C$12:$I$12,0)) -> 6 | F10: =INDEX(Зміни!$C$16:$I$16,MATCH(F$5,Зміни!$C$12:$I$12,0)) -> 6 | G10: =INDEX(Зміни!$C$16:$I$16,MATCH(G$5,Зміни!$C$12:$I$12,0)) -> 6 | H10: =INDEX(Зміни!$C$16:$I$16,MATCH(H$5,Зміни!$C$12:$I$12,0)) -> 6 | I10: =INDEX(Зміни!$C$16:$I$16,MATCH(I$5,Зміни!$C$12:$I$12,0)) -> 6 | J10: =INDEX(Зміни!$C$16:$I$16,MATCH(J$5,Зміни!$C$12:$I$12,0)) -> 6 | K10: =INDEX(Зміни!$C$16:$I$16,MATCH(K$5,Зміни!$C$12:$I$12,0)) -> 6 | ... AH10: =INDEX(Зміни!$C$16:$I$16,MATCH(AH$5,Зміни!$C$12:$I$12,0)) -> 6
A12: СУ-ШЕФ
A13: 1 | B13: Су-шеф | C13: Су-шеф 1 | D13: В | E13: В | F13: В | G13: В | J13: В | K13: В | L13: В | M13: В | P13: Р | Q13: Р | R13: Р | S13: Р | V13: В | W13: В | X13: В | Y13: В | AB13: В | AC13: В | AD13: В | AE13: В | AH13: В | AI13: =COUNTA(D13:AH13) -> 21 | AJ13: =SUMPRODUCT((D13:AH13="Р")*$D$7:$AH$7)+SUMPRODUCT((D13:AH13="С")*$D$8:$AH$8)+SUMPRODUCT((D13:AH13="В")*$D$9:$AH$9)+SUMPRODUCT((D13:AH13="П")*$D$10:$AH$10) -> 156.5 | AK13: =COLUMNS(D13:AH13)-AI13 -> 10 | AL13: =SUMPRODUCT((D13:AH13<>"")*(($D$5:$AH$5="Пт")+($D$5:$AH$5="Сб"))) -> 6 | AM13: =AJ13-Зміни!$C$19 -> -19.5
A14: 2 | B14: Су-шеф | C14: Су-шеф 2 | F14: Р | G14: Р | H14: В | I14: В | L14: Р | M14: Р | N14: В | O14: В | P14: В | T14: Р | U14: Р | V14: Р | W14: Р | Z14: Р | AA14: Р | AB14: Р | AC14: Р | AF14: Р | AG14: Р | AH14: Р | AI14: =COUNTA(D14:AH14) -> 20 | AJ14: =SUMPRODUCT((D14:AH14="Р")*$D$7:$AH$7)+SUMPRODUCT((D14:AH14="С")*$D$8:$AH$8)+SUMPRODUCT((D14:AH14="В")*$D$9:$AH$9)+SUMPRODUCT((D14:AH14="П")*$D$10:$AH$10) -> 149.5 | AK14: =COLUMNS(D14:AH14)-AI14 -> 11 | AL14: =SUMPRODUCT((D14:AH14<>"")*(($D$5:$AH$5="Пт")+($D$5:$AH$5="Сб"))) -> 8 | AM14: =AJ14-Зміни!$C$19 -> -26.5
A15: 3 | B15: Су-шеф | C15: Су-шеф 3 | D15: Р | E15: Р | H15: Р | I15: Р | J15: Р | K15: Р | N15: Р | O15: Р | Q15: В | R15: В | S15: В | T15: В | U15: В | X15: Р | Y15: Р | Z15: В | AA15: В | AD15: Р | AE15: Р | AF15: В | AG15: В | AI15: =COUNTA(D15:AH15) -> 21 | AJ15: =SUMPRODUCT((D15:AH15="Р")*$D$7:$AH$7)+SUMPRODUCT((D15:AH15="С")*$D$8:$AH$8)+SUMPRODUCT((D15:AH15="В")*$D$9:$AH$9)+SUMPRODUCT((D15:AH15="П")*$D$10:$AH$10) -> 157 | AK15: =COLUMNS(D15:AH15)-AI15 -> 10 | AL15: =SUMPRODUCT((D15:AH15<>"")*(($D$5:$AH$5="Пт")+($D$5:$AH$5="Сб"))) -> 6 | AM15: =AJ15-Зміни!$C$19 -> -19
C16: Контроль Р (факт − норма) | D16: =COUNTIF(D$13:D$15,"Р")-INDEX(Норми!$C$12:$I$47,MATCH("Су-шеф|Р",Норми!$L$12:$L$47,0),MATCH(D$5,Норми!$C$11:$I$11,0)) -> 0 | E16: =COUNTIF(E$13:E$15,"Р")-INDEX(Норми!$C$12:$I$47,MATCH("Су-шеф|Р",Норми!$L$12:$L$47,0),MATCH(E$5,Норми!$C$11:$I$11,0)) -> 0 | F16: =COUNTIF(F$13:F$15,"Р")-INDEX(Норми!$C$12:$I$47,MATCH("Су-шеф|Р",Норми!$L$12:$L$47,0),MATCH(F$5,Норми!$C$11:$I$11,0)) -> 0 | G16: =COUNTIF(G$13:G$15,"Р")-INDEX(Норми!$C$12:$I$47,MATCH("Су-шеф|Р",Норми!$L$12:$L$47,0),MATCH(G$5,Норми!$C$11:$I$11,0)) -> 0 | H16: =COUNTIF(H$13:H$15,"Р")-INDEX(Норми!$C$12:$I$47,MATCH("Су-шеф|Р",Норми!$L$12:$L$47,0),MATCH(H$5,Норми!$C$11:$I$11,0)) -> 0 | I16: =COUNTIF(I$13:I$15,"Р")-INDEX(Норми!$C$12:$I$47,MATCH("Су-шеф|Р",Норми!$L$12:$L$47,0),MATCH(I$5,Норми!$C$11:$I$11,0)) -> 0 | J16: =COUNTIF(J$13:J$15,"Р")-INDEX(Норми!$C$12:$I$47,MATCH("Су-шеф|Р",Норми!$L$12:$L$47,0),MATCH(J$5,Норми!$C$11:$I$11,0)) -> 0 | K16: =COUNTIF(K$13:K$15,"Р")-INDEX(Норми!$C$12:$I$47,MATCH("Су-шеф|Р",Норми!$L$12:$L$47,0),MATCH(K$5,Норми!$C$11:$I$11,0)) -> 0 | ... AH16: =COUNTIF(AH$13:AH$15,"Р")-INDEX(Норми!$C$12:$I$47,MATCH("Су-шеф|Р",Норми!$L$12:$L$47,0),MATCH(AH$5,Норми!$C$11:$I$11,0)) -> 0
C17: Контроль В (факт − норма) | D17: =COUNTIF(D$13:D$15,"В")-INDEX(Норми!$C$12:$I$47,MATCH("Су-шеф|В",Норми!$L$12:$L$47,0),MATCH(D$5,Норми!$C$11:$I$11,0)) -> 0 | E17: =COUNTIF(E$13:E$15,"В")-INDEX(Норми!$C$12:$I$47,MATCH("Су-шеф|В",Норми!$L$12:$L$47,0),MATCH(E$5,Норми!$C$11:$I$11,0)) -> 0 | F17: =COUNTIF(F$13:F$15,"В")-INDEX(Норми!$C$12:$I$47,MATCH("Су-шеф|В",Норми!$L$12:$L$47,0),MATCH(F$5,Норми!$C$11:$I$11,0)) -> 0 | G17: =COUNTIF(G$13:G$15,"В")-INDEX(Норми!$C$12:$I$47,MATCH("Су-шеф|В",Норми!$L$12:$L$47,0),MATCH(G$5,Норми!$C$11:$I$11,0)) -> 0 | H17: =COUNTIF(H$13:H$15,"В")-INDEX(Норми!$C$12:$I$47,MATCH("Су-шеф|В",Норми!$L$12:$L$47,0),MATCH(H$5,Норми!$C$11:$I$11,0)) -> 0 | I17: =COUNTIF(I$13:I$15,"В")-INDEX(Норми!$C$12:$I$47,MATCH("Су-шеф|В",Норми!$L$12:$L$47,0),MATCH(I$5,Норми!$C$11:$I$11,0)) -> 0 | J17: =COUNTIF(J$13:J$15,"В")-INDEX(Норми!$C$12:$I$47,MATCH("Су-шеф|В",Норми!$L$12:$L$47,0),MATCH(J$5,Норми!$C$11:$I$11,0)) -> 0 | K17: =COUNTIF(K$13:K$15,"В")-INDEX(Норми!$C$12:$I$47,MATCH("Су-шеф|В",Норми!$L$12:$L$47,0),MATCH(K$5,Норми!$C$11:$I$11,0)) -> 0 | ... AH17: =COUNTIF(AH$13:AH$15,"В")-INDEX(Норми!$C$12:$I$47,MATCH("Су-шеф|В",Норми!$L$12:$L$47,0),MATCH(AH$5,Норми!$C$11:$I$11,0)) -> 0
A19: КУХАР ГРИЛЬ
A20: 4 | B20: Кухар гриль | C20: Кухар гриль 1 | E20: Р | F20: Р | G20: Р | J20: В | K20: В | L20: В | M20: В | N20: С | Q20: В | R20: В | S20: В | T20: В | U20: В | W20: В | X20: В | Y20: В | Z20: В | AA20: В | AD20: В | AE20: В | AF20: В | AG20: В | AH20: В | AI20: =COUNTA(D20:AH20) -> 23 | AJ20: =SUMPRODUCT((D20:AH20="Р")*$D$7:$AH$7)+SUMPRODUCT((D20:AH20="С")*$D$8:$AH$8)+SUMPRODUCT((D20:AH20="В")*$D$9:$AH$9)+SUMPRODUCT((D20:AH20="П")*$D$10:$AH$10) -> 172.5 | AK20: =COLUMNS(D20:AH20)-AI20 -> 8 | AL20: =SUMPRODUCT((D20:AH20<>"")*(($D$5:$AH$5="Пт")+($D$5:$AH$5="Сб"))) -> 10 | AM20: =AJ20-Зміни!$C$19 -> -3.5
A21: 5 | B21: Кухар гриль | C21: Кухар гриль 2 | D21: В | E21: В | F21: В | G21: В | H21: В | K21: В | L21: В | M21: В | N21: В | O21: В | Q21: Р | R21: Р | S21: В | T21: В | X21: Р | Z21: В | AA21: В | AB21: В | AC21: В | AE21: Р | AF21: В | AG21: В | AH21: В | AI21: =COUNTA(D21:AH21) -> 23 | AJ21: =SUMPRODUCT((D21:AH21="Р")*$D$7:$AH$7)+SUMPRODUCT((D21:AH21="С")*$D$8:$AH$8)+SUMPRODUCT((D21:AH21="В")*$D$9:$AH$9)+SUMPRODUCT((D21:AH21="П")*$D$10:$AH$10) -> 171 | AK21: =COLUMNS(D21:AH21)-AI21 -> 8 | AL21: =SUMPRODUCT((D21:AH21<>"")*(($D$5:$AH$5="Пт")+($D$5:$AH$5="Сб"))) -> 10 | AM21: =AJ21-Зміни!$C$19 -> -5
A22: 6 | B22: Кухар гриль | C22: Кухар гриль 3 | D22: В | E22: В | F22: В | H22: Р | I22: В | L22: Р | M22: Р | N22: Р | O22: Р | P22: Р | S22: Р | T22: Р | U22: Р | V22: Р | W22: Р | Y22: Р | Z22: Р | AA22: Р | AB22: Р | AC22: Р | AF22: Р | AG22: Р | AH22: Р | AI22: =COUNTA(D22:AH22) -> 23 | AJ22: =SUMPRODUCT((D22:AH22="Р")*$D$7:$AH$7)+SUMPRODUCT((D22:AH22="С")*$D$8:$AH$8)+SUMPRODUCT((D22:AH22="В")*$D$9:$AH$9)+SUMPRODUCT((D22:AH22="П")*$D$10:$AH$10) -> 172.5 | AK22: =COLUMNS(D22:AH22)-AI22 -> 8 | AL22: =SUMPRODUCT((D22:AH22<>"")*(($D$5:$AH$5="Пт")+($D$5:$AH$5="Сб"))) -> 10 | AM22: =AJ22-Зміни!$C$19 -> -3.5
A23: 7 | B23: Кухар гриль | C23: Кухар гриль 4 | D23: Р | E23: С | F23: С | G23: С | I23: Р | J23: Р | K23: Р | L23: С | M23: С | P23: В | R23: В | S23: С | T23: С | U23: С | V23: В | Y23: В | Z23: С | AA23: С | AB23: С | AD23: Р | AG23: С | AH23: С | AI23: =COUNTA(D23:AH23) -> 22 | AJ23: =SUMPRODUCT((D23:AH23="Р")*$D$7:$AH$7)+SUMPRODUCT((D23:AH23="С")*$D$8:$AH$8)+SUMPRODUCT((D23:AH23="В")*$D$9:$AH$9)+SUMPRODUCT((D23:AH23="П")*$D$10:$AH$10) -> 171.5 | AK23: =COLUMNS(D23:AH23)-AI23 -> 9 | AL23: =SUMPRODUCT((D23:AH23<>"")*(($D$5:$AH$5="Пт")+($D$5:$AH$5="Сб"))) -> 10 | AM23: =AJ23-Зміни!$C$19 -> -4.5
C24: Контроль Р (факт − норма) | D24: =COUNTIF(D$20:D$23,"Р")-INDEX(Норми!$C$12:$I$47,MATCH("Кухар гриль|Р",Норми!$L$12:$L$47,0),MATCH(D$5,Норми!$C$11:$I$11,0)) -> 0 | E24: =COUNTIF(E$20:E$23,"Р")-INDEX(Норми!$C$12:$I$47,MATCH("Кухар гриль|Р",Норми!$L$12:$L$47,0),MATCH(E$5,Норми!$C$11:$I$11,0)) -> 0 | F24: =COUNTIF(F$20:F$23,"Р")-INDEX(Норми!$C$12:$I$47,MATCH("Кухар гриль|Р",Норми!$L$12:$L$47,0),MATCH(F$5,Норми!$C$11:$I$11,0)) -> 0 | G24: =COUNTIF(G$20:G$23,"Р")-INDEX(Норми!$C$12:$I$47,MATCH("Кухар гриль|Р",Норми!$L$12:$L$47,0),MATCH(G$5,Норми!$C$11:$I$11,0)) -> 0 | H24: =COUNTIF(H$20:H$23,"Р")-INDEX(Норми!$C$12:$I$47,MATCH("Кухар гриль|Р",Норми!$L$12:$L$47,0),MATCH(H$5,Норми!$C$11:$I$11,0)) -> 0 | I24: =COUNTIF(I$20:I$23,"Р")-INDEX(Норми!$C$12:$I$47,MATCH("Кухар гриль|Р",Норми!$L$12:$L$47,0),MATCH(I$5,Норми!$C$11:$I$11,0)) -> 0 | J24: =COUNTIF(J$20:J$23,"Р")-INDEX(Норми!$C$12:$I$47,MATCH("Кухар гриль|Р",Норми!$L$12:$L$47,0),MATCH(J$5,Норми!$C$11:$I$11,0)) -> 0 | K24: =COUNTIF(K$20:K$23,"Р")-INDEX(Норми!$C$12:$I$47,MATCH("Кухар гриль|Р",Норми!$L$12:$L$47,0),MATCH(K$5,Норми!$C$11:$I$11,0)) -> 0 | ... AH24: =COUNTIF(AH$20:AH$23,"Р")-INDEX(Норми!$C$12:$I$47,MATCH("Кухар гриль|Р",Норми!$L$12:$L$47,0),MATCH(AH$5,Норми!$C$11:$I$11,0)) -> 0
C25: Контроль С (факт − норма) | D25: =COUNTIF(D$20:D$23,"С")-INDEX(Норми!$C$12:$I$47,MATCH("Кухар гриль|С",Норми!$L$12:$L$47,0),MATCH(D$5,Норми!$C$11:$I$11,0)) -> 0 | E25: =COUNTIF(E$20:E$23,"С")-INDEX(Норми!$C$12:$I$47,MATCH("Кухар гриль|С",Норми!$L$12:$L$47,0),MATCH(E$5,Норми!$C$11:$I$11,0)) -> 0 | F25: =COUNTIF(F$20:F$23,"С")-INDEX(Норми!$C$12:$I$47,MATCH("Кухар гриль|С",Норми!$L$12:$L$47,0),MATCH(F$5,Норми!$C$11:$I$11,0)) -> 0 | G25: =COUNTIF(G$20:G$23,"С")-INDEX(Норми!$C$12:$I$47,MATCH("Кухар гриль|С",Норми!$L$12:$L$47,0),MATCH(G$5,Норми!$C$11:$I$11,0)) -> 0 | H25: =COUNTIF(H$20:H$23,"С")-INDEX(Норми!$C$12:$I$47,MATCH("Кухар гриль|С",Норми!$L$12:$L$47,0),MATCH(H$5,Норми!$C$11:$I$11,0)) -> 0 | I25: =COUNTIF(I$20:I$23,"С")-INDEX(Норми!$C$12:$I$47,MATCH("Кухар гриль|С",Норми!$L$12:$L$47,0),MATCH(I$5,Норми!$C$11:$I$11,0)) -> 0 | J25: =COUNTIF(J$20:J$23,"С")-INDEX(Норми!$C$12:$I$47,MATCH("Кухар гриль|С",Норми!$L$12:$L$47,0),MATCH(J$5,Норми!$C$11:$I$11,0)) -> 0 | K25: =COUNTIF(K$20:K$23,"С")-INDEX(Норми!$C$12:$I$47,MATCH("Кухар гриль|С",Норми!$L$12:$L$47,0),MATCH(K$5,Норми!$C$11:$I$11,0)) -> 0 | ... AH25: =COUNTIF(AH$20:AH$23,"С")-INDEX(Норми!$C$12:$I$47,MATCH("Кухар гриль|С",Норми!$L$12:$L$47,0),MATCH(AH$5,Норми!$C$11:$I$11,0)) -> 0
C26: Контроль В (факт − норма) | D26: =COUNTIF(D$20:D$23,"В")-INDEX(Норми!$C$12:$I$47,MATCH("Кухар гриль|В",Норми!$L$12:$L$47,0),MATCH(D$5,Норми!$C$11:$I$11,0)) -> 0 | E26: =COUNTIF(E$20:E$23,"В")-INDEX(Норми!$C$12:$I$47,MATCH("Кухар гриль|В",Норми!$L$12:$L$47,0),MATCH(E$5,Норми!$C$11:$I$11,0)) -> 0 | F26: =COUNTIF(F$20:F$23,"В")-INDEX(Норми!$C$12:$I$47,MATCH("Кухар гриль|В",Норми!$L$12:$L$47,0),MATCH(F$5,Норми!$C$11:$I$11,0)) -> 0 | G26: =COUNTIF(G$20:G$23,"В")-INDEX(Норми!$C$12:$I$47,MATCH("Кухар гриль|В",Норми!$L$12:$L$47,0),MATCH(G$5,Норми!$C$11:$I$11,0)) -> 0 | H26: =COUNTIF(H$20:H$23,"В")-INDEX(Норми!$C$12:$I$47,MATCH("Кухар гриль|В",Норми!$L$12:$L$47,0),MATCH(H$5,Норми!$C$11:$I$11,0)) -> 0 | I26: =COUNTIF(I$20:I$23,"В")-INDEX(Норми!$C$12:$I$47,MATCH("Кухар гриль|В",Норми!$L$12:$L$47,0),MATCH(I$5,Норми!$C$11:$I$11,0)) -> 0 | J26: =COUNTIF(J$20:J$23,"В")-INDEX(Норми!$C$12:$I$47,MATCH("Кухар гриль|В",Норми!$L$12:$L$47,0),MATCH(J$5,Норми!$C$11:$I$11,0)) -> 0 | K26: =COUNTIF(K$20:K$23,"В")-INDEX(Норми!$C$12:$I$47,MATCH("Кухар гриль|В",Норми!$L$12:$L$47,0),MATCH(K$5,Норми!$C$11:$I$11,0)) -> 0 | ... AH26: =COUNTIF(AH$20:AH$23,"В")-INDEX(Норми!$C$12:$I$47,MATCH("Кухар гриль|В",Норми!$L$12:$L$47,0),MATCH(AH$5,Норми!$C$11:$I$11,0)) -> 0
A28: КУХАР ГАРЯЧОГО ЦЕХУ
A29: 8 | B29: Кухар гарячого цеху | C29: Кухар гарячого цеху 1 | E29: Р | F29: Р | G29: Р | H29: Р | I29: Р | L29: Р | M29: С | N29: С | O29: В | P29: В | S29: В | T29: С | U29: С | Y29: В | Z29: В | AA29: В | AC29: Р | AD29: Р | AG29: В | AH29: В | AI29: =COUNTA(D29:AH29) -> 20 | AJ29: =SUMPRODUCT((D29:AH29="Р")*$D$7:$AH$7)+SUMPRODUCT((D29:AH29="С")*$D$8:$AH$8)+SUMPRODUCT((D29:AH29="В")*$D$9:$AH$9)+SUMPRODUCT((D29:AH29="П")*$D$10:$AH$10) -> 152 | AK29: =COLUMNS(D29:AH29)-AI29 -> 11 | AL29: =SUMPRODUCT((D29:AH29<>"")*(($D$5:$AH$5="Пт")+($D$5:$AH$5="Сб"))) -> 10 | AM29: =AJ29-Зміни!$C$19 -> -24
A30: 9 | B30: Кухар гарячого цеху | C30: Кухар гарячого цеху 2 | D30: В | E30: В | F30: В | G30: В | J30: Р | M30: Р | N30: Р | O30: Р | P30: Р | Q30: Р | T30: Р | U30: Р | V30: Р | W30: Р | Z30: В | AA30: В | AB30: В | AC30: В | AF30: В | AG30: В | AH30: В | AI30: =COUNTA(D30:AH30) -> 21 | AJ30: =SUMPRODUCT((D30:AH30="Р")*$D$7:$AH$7)+SUMPRODUCT((D30:AH30="С")*$D$8:$AH$8)+SUMPRODUCT((D30:AH30="В")*$D$9:$AH$9)+SUMPRODUCT((D30:AH30="П")*$D$10:$AH$10) -> 156.5 | AK30: =COLUMNS(D30:AH30)-AI30 -> 10 | AL30: =SUMPRODUCT((D30:AH30<>"")*(($D$5:$AH$5="Пт")+($D$5:$AH$5="Сб"))) -> 8 | AM30: =AJ30-Зміни!$C$19 -> -19.5
A31: 10 | B31: Кухар гарячого цеху | C31: Кухар гарячого цеху 3 | F31: С | G31: С | H31: В | K31: Р | L31: В | M31: В | N31: В | R31: Р | S31: Р | T31: В | U31: В | V31: В | X31: Р | Y31: Р | Z31: Р | AA31: С | AB31: С | AD31: В | AE31: В | AH31: С | AI31: =COUNTA(D31:AH31) -> 20 | AJ31: =SUMPRODUCT((D31:AH31="Р")*$D$7:$AH$7)+SUMPRODUCT((D31:AH31="С")*$D$8:$AH$8)+SUMPRODUCT((D31:AH31="В")*$D$9:$AH$9)+SUMPRODUCT((D31:AH31="П")*$D$10:$AH$10) -> 151.5 | AK31: =COLUMNS(D31:AH31)-AI31 -> 11 | AL31: =SUMPRODUCT((D31:AH31<>"")*(($D$5:$AH$5="Пт")+($D$5:$AH$5="Сб"))) -> 8 | AM31: =AJ31-Зміни!$C$19 -> -24.5
A32: 11 | B32: Кухар гарячого цеху | C32: Кухар гарячого цеху 4 | D32: Р | E32: В | F32: В | I32: В | J32: В | K32: В | L32: В | M32: В | Q32: В | R32: В | S32: В | T32: В | W32: В | X32: В | AA32: Р | AB32: Р | AE32: Р | AF32: Р | AG32: Р | AH32: Р | AI32: =COUNTA(D32:AH32) -> 20 | AJ32: =SUMPRODUCT((D32:AH32="Р")*$D$7:$AH$7)+SUMPRODUCT((D32:AH32="С")*$D$8:$AH$8)+SUMPRODUCT((D32:AH32="В")*$D$9:$AH$9)+SUMPRODUCT((D32:AH32="П")*$D$10:$AH$10) -> 150 | AK32: =COLUMNS(D32:AH32)-AI32 -> 11 | AL32: =SUMPRODUCT((D32:AH32<>"")*(($D$5:$AH$5="Пт")+($D$5:$AH$5="Сб"))) -> 9 | AM32: =AJ32-Зміни!$C$19 -> -26
